2023-12-31 09:15:58,341 (__init__.py:1088 MainThread) ERROR - TeleBot: "Threaded polling exception: A request to the Telegram API was unsuccessful. Error code: 409. Description: Conflict: terminated by other getUpdates request; make sure that only one bot instance is running"
2023-12-31 09:15:58,341 (__init__.py:1090 MainThread) ERROR - TeleBot: "Exception traceback:
Traceback (most recent call last):
  File "/usr/local/lib/python3.10/dist-packages/telebot/__init__.py", line 1081, in __threaded_polling
    polling_thread.raise_exceptions()
  File "/usr/local/lib/python3.10/dist-packages/telebot/util.py", line 108, in raise_exceptions
    raise self.exception_info
  File "/usr/local/lib/python3.10/dist-packages/telebot/util.py", line 90, in run
    task(*args, **kwargs)
  File "/usr/local/lib/python3.10/dist-packages/telebot/__init__.py", line 651, in __retrieve_updates
    updates = self.get_updates(offset=(self.last_update_id + 1),
  File "/usr/local/lib/python3.10/dist-packages/telebot/__init__.py", line 625, in get_updates
    json_updates = apihelper.get_updates(self.token, offset, limit, timeout, allowed_updates, long_polling_timeout)
  File "/usr/local/lib/python3.10/dist-packages/telebot/apihelper.py", line 323, in get_updates
    return _make_request(token, method_url, params=payload)
  File "/usr/local/lib/python3.10/dist-packages/telebot/apihelper.py", line 164, in _make_request
    json_result = _check_result(method_name, result)
  File "/usr/local/lib/python3.10/dist-packages/telebot/apihelper.py", line 191, in _check_result
    raise ApiTelegramException(method_name, result, result_json)
telebot.apihelper.ApiTelegramException: A request to the Telegram API was unsuccessful. Error code: 409. Description: Conflict: terminated by other getUpdates request; make sure that only one bot instance is running
"
2023-12-31 09:16:01,651 (__init__.py:1088 MainThread) ERROR - TeleBot: "Threaded polling exception: A request to the Telegram API was unsuccessful. Error code: 409. Description: Conflict: terminated by other getUpdates request; make sure that only one bot instance is running"
2023-12-31 09:16:01,651 (__init__.py:1090 MainThread) ERROR - TeleBot: "Exception traceback:
Traceback (most recent call last):
  File "/usr/local/lib/python3.10/dist-packages/telebot/__init__.py", line 1081, in __threaded_polling
    polling_thread.raise_exceptions()
  File "/usr/local/lib/python3.10/dist-packages/telebot/util.py", line 108, in raise_exceptions
    raise self.exception_info
  File "/usr/local/lib/python3.10/dist-packages/telebot/util.py", line 90, in run
    task(*args, **kwargs)
  File "/usr/local/lib/python3.10/dist-packages/telebot/__init__.py", line 651, in __retrieve_updates
    updates = self.get_updates(offset=(self.last_update_id + 1),
  File "/usr/local/lib/python3.10/dist-packages/telebot/__init__.py", line 625, in get_updates
    json_updates = apihelper.get_updates(self.token, offset, limit, timeout, allowed_updates, long_polling_timeout)
  File "/usr/local/lib/python3.10/dist-packages/telebot/apihelper.py", line 323, in get_updates
    return _make_request(token, method_url, params=payload)
  File "/usr/local/lib/python3.10/dist-packages/telebot/apihelper.py", line 164, in _make_request
    json_result = _check_result(method_name, result)
  File "/usr/local/lib/python3.10/dist-packages/telebot/apihelper.py", line 191, in _check_result
    raise ApiTelegramException(method_name, result, result_json)
telebot.apihelper.ApiTelegramException: A request to the Telegram API was unsuccessful. Error code: 409. Description: Conflict: terminated by other getUpdates request; make sure that only one bot instance is running
"
2023-12-31 09:16:02,011 (__init__.py:1088 MainThread) ERROR - TeleBot: "Threaded polling exception: A request to the Telegram API was unsuccessful. Error code: 409. Description: Conflict: terminated by other getUpdates request; make sure that only one bot instance is running"
2023-12-31 09:16:02,012 (__init__.py:1090 MainThread) ERROR - TeleBot: "Exception traceback:
Traceback (most recent call last):
  File "/usr/local/lib/python3.10/dist-packages/telebot/__init__.py", line 1081, in __threaded_polling
    polling_thread.raise_exceptions()
  File "/usr/local/lib/python3.10/dist-packages/telebot/util.py", line 108, in raise_exceptions
    raise self.exception_info
  File "/usr/local/lib/python3.10/dist-packages/telebot/util.py", line 90, in run
    task(*args, **kwargs)
  File "/usr/local/lib/python3.10/dist-packages/telebot/__init__.py", line 651, in __retrieve_updates
    updates = self.get_updates(offset=(self.last_update_id + 1),
  File "/usr/local/lib/python3.10/dist-packages/telebot/__init__.py", line 625, in get_updates
    json_updates = apihelper.get_updates(self.token, offset, limit, timeout, allowed_updates, long_polling_timeout)
  File "/usr/local/lib/python3.10/dist-packages/telebot/apihelper.py", line 323, in get_updates
    return _make_request(token, method_url, params=payload)
  File "/usr/local/lib/python3.10/dist-packages/telebot/apihelper.py", line 164, in _make_request
    json_result = _check_result(method_name, result)
  File "/usr/local/lib/python3.10/dist-packages/telebot/apihelper.py", line 191, in _check_result
    raise ApiTelegramException(method_name, result, result_json)
telebot.apihelper.ApiTelegramException: A request to the Telegram API was unsuccessful. Error code: 409. Description: Conflict: terminated by other getUpdates request; make sure that only one bot instance is running
"
2023-12-31 09:16:05,572 (__init__.py:1088 MainThread) ERROR - TeleBot: "Threaded polling exception: A request to the Telegram API was unsuccessful. Error code: 409. Description: Conflict: terminated by other getUpdates request; make sure that only one bot instance is running"
2023-12-31 09:16:05,572 (__init__.py:1090 MainThread) ERROR - TeleBot: "Exception traceback:
Traceback (most recent call last):
  File "/usr/local/lib/python3.10/dist-packages/telebot/__init__.py", line 1081, in __threaded_polling
    polling_thread.raise_exceptions()
  File "/usr/local/lib/python3.10/dist-packages/telebot/util.py", line 108, in raise_exceptions
    raise self.exception_info
  File "/usr/local/lib/python3.10/dist-packages/telebot/util.py", line 90, in run
    task(*args, **kwargs)
  File "/usr/local/lib/python3.10/dist-packages/telebot/__init__.py", line 651, in __retrieve_updates
    updates = self.get_updates(offset=(self.last_update_id + 1),
  File "/usr/local/lib/python3.10/dist-packages/telebot/__init__.py", line 625, in get_updates
    json_updates = apihelper.get_updates(self.token, offset, limit, timeout, allowed_updates, long_polling_timeout)
  File "/usr/local/lib/python3.10/dist-packages/telebot/apihelper.py", line 323, in get_updates
    return _make_request(token, method_url, params=payload)
  File "/usr/local/lib/python3.10/dist-packages/telebot/apihelper.py", line 164, in _make_request
    json_result = _check_result(method_name, result)
  File "/usr/local/lib/python3.10/dist-packages/telebot/apihelper.py", line 191, in _check_result
    raise ApiTelegramException(method_name, result, result_json)
telebot.apihelper.ApiTelegramException: A request to the Telegram API was unsuccessful. Error code: 409. Description: Conflict: terminated by other getUpdates request; make sure that only one bot instance is running
"
2023-12-31 09:16:06,133 (__init__.py:1088 MainThread) ERROR - TeleBot: "Threaded polling exception: A request to the Telegram API was unsuccessful. Error code: 409. Description: Conflict: terminated by other getUpdates request; make sure that only one bot instance is running"
2023-12-31 09:16:06,133 (__init__.py:1090 MainThread) ERROR - TeleBot: "Exception traceback:
Traceback (most recent call last):
  File "/usr/local/lib/python3.10/dist-packages/telebot/__init__.py", line 1081, in __threaded_polling
    polling_thread.raise_exceptions()
  File "/usr/local/lib/python3.10/dist-packages/telebot/util.py", line 108, in raise_exceptions
    raise self.exception_info
  File "/usr/local/lib/python3.10/dist-packages/telebot/util.py", line 90, in run
    task(*args, **kwargs)
  File "/usr/local/lib/python3.10/dist-packages/telebot/__init__.py", line 651, in __retrieve_updates
    updates = self.get_updates(offset=(self.last_update_id + 1),
  File "/usr/local/lib/python3.10/dist-packages/telebot/__init__.py", line 625, in get_updates
    json_updates = apihelper.get_updates(self.token, offset, limit, timeout, allowed_updates, long_polling_timeout)
  File "/usr/local/lib/python3.10/dist-packages/telebot/apihelper.py", line 323, in get_updates
    return _make_request(token, method_url, params=payload)
  File "/usr/local/lib/python3.10/dist-packages/telebot/apihelper.py", line 164, in _make_request
    json_result = _check_result(method_name, result)
  File "/usr/local/lib/python3.10/dist-packages/telebot/apihelper.py", line 191, in _check_result
    raise ApiTelegramException(method_name, result, result_json)
telebot.apihelper.ApiTelegramException: A request to the Telegram API was unsuccessful. Error code: 409. Description: Conflict: terminated by other getUpdates request; make sure that only one bot instance is running
"
2023-12-31 09:16:10,192 (__init__.py:1088 MainThread) ERROR - TeleBot: "Threaded polling exception: A request to the Telegram API was unsuccessful. Error code: 409. Description: Conflict: terminated by other getUpdates request; make sure that only one bot instance is running"
2023-12-31 09:16:10,192 (__init__.py:1090 MainThread) ERROR - TeleBot: "Exception traceback:
Traceback (most recent call last):
  File "/usr/local/lib/python3.10/dist-packages/telebot/__init__.py", line 1081, in __threaded_polling
    polling_thread.raise_exceptions()
  File "/usr/local/lib/python3.10/dist-packages/telebot/util.py", line 108, in raise_exceptions
    raise self.exception_info
  File "/usr/local/lib/python3.10/dist-packages/telebot/util.py", line 90, in run
    task(*args, **kwargs)
  File "/usr/local/lib/python3.10/dist-packages/telebot/__init__.py", line 651, in __retrieve_updates
    updates = self.get_updates(offset=(self.last_update_id + 1),
  File "/usr/local/lib/python3.10/dist-packages/telebot/__init__.py", line 625, in get_updates
    json_updates = apihelper.get_updates(self.token, offset, limit, timeout, allowed_updates, long_polling_timeout)
  File "/usr/local/lib/python3.10/dist-packages/telebot/apihelper.py", line 323, in get_updates
    return _make_request(token, method_url, params=payload)
  File "/usr/local/lib/python3.10/dist-packages/telebot/apihelper.py", line 164, in _make_request
    json_result = _check_result(method_name, result)
  File "/usr/local/lib/python3.10/dist-packages/telebot/apihelper.py", line 191, in _check_result
    raise ApiTelegramException(method_name, result, result_json)
telebot.apihelper.ApiTelegramException: A request to the Telegram API was unsuccessful. Error code: 409. Description: Conflict: terminated by other getUpdates request; make sure that only one bot instance is running
"
2023-12-31 09:16:11,251 (__init__.py:1088 MainThread) ERROR - TeleBot: "Threaded polling exception: A request to the Telegram API was unsuccessful. Error code: 409. Description: Conflict: terminated by other getUpdates request; make sure that only one bot instance is running"
2023-12-31 09:16:11,252 (__init__.py:1090 MainThread) ERROR - TeleBot: "Exception traceback:
Traceback (most recent call last):
  File "/usr/local/lib/python3.10/dist-packages/telebot/__init__.py", line 1081, in __threaded_polling
    polling_thread.raise_exceptions()
  File "/usr/local/lib/python3.10/dist-packages/telebot/util.py", line 108, in raise_exceptions
    raise self.exception_info
  File "/usr/local/lib/python3.10/dist-packages/telebot/util.py", line 90, in run
    task(*args, **kwargs)
  File "/usr/local/lib/python3.10/dist-packages/telebot/__init__.py", line 651, in __retrieve_updates
    updates = self.get_updates(offset=(self.last_update_id + 1),
  File "/usr/local/lib/python3.10/dist-packages/telebot/__init__.py", line 625, in get_updates
    json_updates = apihelper.get_updates(self.token, offset, limit, timeout, allowed_updates, long_polling_timeout)
  File "/usr/local/lib/python3.10/dist-packages/telebot/apihelper.py", line 323, in get_updates
    return _make_request(token, method_url, params=payload)
  File "/usr/local/lib/python3.10/dist-packages/telebot/apihelper.py", line 164, in _make_request
    json_result = _check_result(method_name, result)
  File "/usr/local/lib/python3.10/dist-packages/telebot/apihelper.py", line 191, in _check_result
    raise ApiTelegramException(method_name, result, result_json)
telebot.apihelper.ApiTelegramException: A request to the Telegram API was unsuccessful. Error code: 409. Description: Conflict: terminated by other getUpdates request; make sure that only one bot instance is running
"
2023-12-31 09:16:16,313 (__init__.py:1088 MainThread) ERROR - TeleBot: "Threaded polling exception: A request to the Telegram API was unsuccessful. Error code: 409. Description: Conflict: terminated by other getUpdates request; make sure that only one bot instance is running"
2023-12-31 09:16:16,314 (__init__.py:1090 MainThread) ERROR - TeleBot: "Exception traceback:
Traceback (most recent call last):
  File "/usr/local/lib/python3.10/dist-packages/telebot/__init__.py", line 1081, in __threaded_polling
    polling_thread.raise_exceptions()
  File "/usr/local/lib/python3.10/dist-packages/telebot/util.py", line 108, in raise_exceptions
    raise self.exception_info
  File "/usr/local/lib/python3.10/dist-packages/telebot/util.py", line 90, in run
    task(*args, **kwargs)
  File "/usr/local/lib/python3.10/dist-packages/telebot/__init__.py", line 651, in __retrieve_updates
    updates = self.get_updates(offset=(self.last_update_id + 1),
  File "/usr/local/lib/python3.10/dist-packages/telebot/__init__.py", line 625, in get_updates
    json_updates = apihelper.get_updates(self.token, offset, limit, timeout, allowed_updates, long_polling_timeout)
  File "/usr/local/lib/python3.10/dist-packages/telebot/apihelper.py", line 323, in get_updates
    return _make_request(token, method_url, params=payload)
  File "/usr/local/lib/python3.10/dist-packages/telebot/apihelper.py", line 164, in _make_request
    json_result = _check_result(method_name, result)
  File "/usr/local/lib/python3.10/dist-packages/telebot/apihelper.py", line 191, in _check_result
    raise ApiTelegramException(method_name, result, result_json)
telebot.apihelper.ApiTelegramException: A request to the Telegram API was unsuccessful. Error code: 409. Description: Conflict: terminated by other getUpdates request; make sure that only one bot instance is running
"
2023-12-31 09:16:18,374 (__init__.py:1088 MainThread) ERROR - TeleBot: "Threaded polling exception: A request to the Telegram API was unsuccessful. Error code: 409. Description: Conflict: terminated by other getUpdates request; make sure that only one bot instance is running"
2023-12-31 09:16:18,374 (__init__.py:1090 MainThread) ERROR - TeleBot: "Exception traceback:
Traceback (most recent call last):
  File "/usr/local/lib/python3.10/dist-packages/telebot/__init__.py", line 1081, in __threaded_polling
    polling_thread.raise_exceptions()
  File "/usr/local/lib/python3.10/dist-packages/telebot/util.py", line 108, in raise_exceptions
    raise self.exception_info
  File "/usr/local/lib/python3.10/dist-packages/telebot/util.py", line 90, in run
    task(*args, **kwargs)
  File "/usr/local/lib/python3.10/dist-packages/telebot/__init__.py", line 651, in __retrieve_updates
    updates = self.get_updates(offset=(self.last_update_id + 1),
  File "/usr/local/lib/python3.10/dist-packages/telebot/__init__.py", line 625, in get_updates
    json_updates = apihelper.get_updates(self.token, offset, limit, timeout, allowed_updates, long_polling_timeout)
  File "/usr/local/lib/python3.10/dist-packages/telebot/apihelper.py", line 323, in get_updates
    return _make_request(token, method_url, params=payload)
  File "/usr/local/lib/python3.10/dist-packages/telebot/apihelper.py", line 164, in _make_request
    json_result = _check_result(method_name, result)
  File "/usr/local/lib/python3.10/dist-packages/telebot/apihelper.py", line 191, in _check_result
    raise ApiTelegramException(method_name, result, result_json)
telebot.apihelper.ApiTelegramException: A request to the Telegram API was unsuccessful. Error code: 409. Description: Conflict: terminated by other getUpdates request; make sure that only one bot instance is running
"
2023-12-31 09:16:22,445 (__init__.py:1088 MainThread) ERROR - TeleBot: "Threaded polling exception: A request to the Telegram API was unsuccessful. Error code: 409. Description: Conflict: terminated by other getUpdates request; make sure that only one bot instance is running"
2023-12-31 09:16:22,446 (__init__.py:1090 MainThread) ERROR - TeleBot: "Exception traceback:
Traceback (most recent call last):
  File "/usr/local/lib/python3.10/dist-packages/telebot/__init__.py", line 1081, in __threaded_polling
    polling_thread.raise_exceptions()
  File "/usr/local/lib/python3.10/dist-packages/telebot/util.py", line 108, in raise_exceptions
    raise self.exception_info
  File "/usr/local/lib/python3.10/dist-packages/telebot/util.py", line 90, in run
    task(*args, **kwargs)
  File "/usr/local/lib/python3.10/dist-packages/telebot/__init__.py", line 651, in __retrieve_updates
    updates = self.get_updates(offset=(self.last_update_id + 1),
  File "/usr/local/lib/python3.10/dist-packages/telebot/__init__.py", line 625, in get_updates
    json_updates = apihelper.get_updates(self.token, offset, limit, timeout, allowed_updates, long_polling_timeout)
  File "/usr/local/lib/python3.10/dist-packages/telebot/apihelper.py", line 323, in get_updates
    return _make_request(token, method_url, params=payload)
  File "/usr/local/lib/python3.10/dist-packages/telebot/apihelper.py", line 164, in _make_request
    json_result = _check_result(method_name, result)
  File "/usr/local/lib/python3.10/dist-packages/telebot/apihelper.py", line 191, in _check_result
    raise ApiTelegramException(method_name, result, result_json)
telebot.apihelper.ApiTelegramException: A request to the Telegram API was unsuccessful. Error code: 409. Description: Conflict: terminated by other getUpdates request; make sure that only one bot instance is running
"
2023-12-31 09:16:26,505 (__init__.py:1088 MainThread) ERROR - TeleBot: "Threaded polling exception: A request to the Telegram API was unsuccessful. Error code: 409. Description: Conflict: terminated by other getUpdates request; make sure that only one bot instance is running"
2023-12-31 09:16:26,505 (__init__.py:1090 MainThread) ERROR - TeleBot: "Exception traceback:
Traceback (most recent call last):
  File "/usr/local/lib/python3.10/dist-packages/telebot/__init__.py", line 1081, in __threaded_polling
    polling_thread.raise_exceptions()
  File "/usr/local/lib/python3.10/dist-packages/telebot/util.py", line 108, in raise_exceptions
    raise self.exception_info
  File "/usr/local/lib/python3.10/dist-packages/telebot/util.py", line 90, in run
    task(*args, **kwargs)
  File "/usr/local/lib/python3.10/dist-packages/telebot/__init__.py", line 651, in __retrieve_updates
    updates = self.get_updates(offset=(self.last_update_id + 1),
  File "/usr/local/lib/python3.10/dist-packages/telebot/__init__.py", line 625, in get_updates
    json_updates = apihelper.get_updates(self.token, offset, limit, timeout, allowed_updates, long_polling_timeout)
  File "/usr/local/lib/python3.10/dist-packages/telebot/apihelper.py", line 323, in get_updates
    return _make_request(token, method_url, params=payload)
  File "/usr/local/lib/python3.10/dist-packages/telebot/apihelper.py", line 164, in _make_request
    json_result = _check_result(method_name, result)
  File "/usr/local/lib/python3.10/dist-packages/telebot/apihelper.py", line 191, in _check_result
    raise ApiTelegramException(method_name, result, result_json)
telebot.apihelper.ApiTelegramException: A request to the Telegram API was unsuccessful. Error code: 409. Description: Conflict: terminated by other getUpdates request; make sure that only one bot instance is running
"
2023-12-31 09:16:29,810 (__init__.py:1088 MainThread) ERROR - TeleBot: "Threaded polling exception: A request to the Telegram API was unsuccessful. Error code: 409. Description: Conflict: terminated by other getUpdates request; make sure that only one bot instance is running"
2023-12-31 09:16:29,810 (__init__.py:1090 MainThread) ERROR - TeleBot: "Exception traceback:
Traceback (most recent call last):
  File "/usr/local/lib/python3.10/dist-packages/telebot/__init__.py", line 1081, in __threaded_polling
    polling_thread.raise_exceptions()
  File "/usr/local/lib/python3.10/dist-packages/telebot/util.py", line 108, in raise_exceptions
    raise self.exception_info
  File "/usr/local/lib/python3.10/dist-packages/telebot/util.py", line 90, in run
    task(*args, **kwargs)
  File "/usr/local/lib/python3.10/dist-packages/telebot/__init__.py", line 651, in __retrieve_updates
    updates = self.get_updates(offset=(self.last_update_id + 1),
  File "/usr/local/lib/python3.10/dist-packages/telebot/__init__.py", line 625, in get_updates
    json_updates = apihelper.get_updates(self.token, offset, limit, timeout, allowed_updates, long_polling_timeout)
  File "/usr/local/lib/python3.10/dist-packages/telebot/apihelper.py", line 323, in get_updates
    return _make_request(token, method_url, params=payload)
  File "/usr/local/lib/python3.10/dist-packages/telebot/apihelper.py", line 164, in _make_request
    json_result = _check_result(method_name, result)
  File "/usr/local/lib/python3.10/dist-packages/telebot/apihelper.py", line 191, in _check_result
    raise ApiTelegramException(method_name, result, result_json)
telebot.apihelper.ApiTelegramException: A request to the Telegram API was unsuccessful. Error code: 409. Description: Conflict: terminated by other getUpdates request; make sure that only one bot instance is running
"
2023-12-31 09:16:37,867 (__init__.py:1088 MainThread) ERROR - TeleBot: "Threaded polling exception: A request to the Telegram API was unsuccessful. Error code: 409. Description: Conflict: terminated by other getUpdates request; make sure that only one bot instance is running"
2023-12-31 09:16:37,867 (__init__.py:1090 MainThread) ERROR - TeleBot: "Exception traceback:
Traceback (most recent call last):
  File "/usr/local/lib/python3.10/dist-packages/telebot/__init__.py", line 1081, in __threaded_polling
    polling_thread.raise_exceptions()
  File "/usr/local/lib/python3.10/dist-packages/telebot/util.py", line 108, in raise_exceptions
    raise self.exception_info
  File "/usr/local/lib/python3.10/dist-packages/telebot/util.py", line 90, in run
    task(*args, **kwargs)
  File "/usr/local/lib/python3.10/dist-packages/telebot/__init__.py", line 651, in __retrieve_updates
    updates = self.get_updates(offset=(self.last_update_id + 1),
  File "/usr/local/lib/python3.10/dist-packages/telebot/__init__.py", line 625, in get_updates
    json_updates = apihelper.get_updates(self.token, offset, limit, timeout, allowed_updates, long_polling_timeout)
  File "/usr/local/lib/python3.10/dist-packages/telebot/apihelper.py", line 323, in get_updates
    return _make_request(token, method_url, params=payload)
  File "/usr/local/lib/python3.10/dist-packages/telebot/apihelper.py", line 164, in _make_request
    json_result = _check_result(method_name, result)
  File "/usr/local/lib/python3.10/dist-packages/telebot/apihelper.py", line 191, in _check_result
    raise ApiTelegramException(method_name, result, result_json)
telebot.apihelper.ApiTelegramException: A request to the Telegram API was unsuccessful. Error code: 409. Description: Conflict: terminated by other getUpdates request; make sure that only one bot instance is running
"
2023-12-31 09:16:41,172 (__init__.py:1088 MainThread) ERROR - TeleBot: "Threaded polling exception: A request to the Telegram API was unsuccessful. Error code: 409. Description: Conflict: terminated by other getUpdates request; make sure that only one bot instance is running"
2023-12-31 09:16:41,172 (__init__.py:1090 MainThread) ERROR - TeleBot: "Exception traceback:
Traceback (most recent call last):
  File "/usr/local/lib/python3.10/dist-packages/telebot/__init__.py", line 1081, in __threaded_polling
    polling_thread.raise_exceptions()
  File "/usr/local/lib/python3.10/dist-packages/telebot/util.py", line 108, in raise_exceptions
    raise self.exception_info
  File "/usr/local/lib/python3.10/dist-packages/telebot/util.py", line 90, in run
    task(*args, **kwargs)
  File "/usr/local/lib/python3.10/dist-packages/telebot/__init__.py", line 651, in __retrieve_updates
    updates = self.get_updates(offset=(self.last_update_id + 1),
  File "/usr/local/lib/python3.10/dist-packages/telebot/__init__.py", line 625, in get_updates
    json_updates = apihelper.get_updates(self.token, offset, limit, timeout, allowed_updates, long_polling_timeout)
  File "/usr/local/lib/python3.10/dist-packages/telebot/apihelper.py", line 323, in get_updates
    return _make_request(token, method_url, params=payload)
  File "/usr/local/lib/python3.10/dist-packages/telebot/apihelper.py", line 164, in _make_request
    json_result = _check_result(method_name, result)
  File "/usr/local/lib/python3.10/dist-packages/telebot/apihelper.py", line 191, in _check_result
    raise ApiTelegramException(method_name, result, result_json)
telebot.apihelper.ApiTelegramException: A request to the Telegram API was unsuccessful. Error code: 409. Description: Conflict: terminated by other getUpdates request; make sure that only one bot instance is running
"
2023-12-31 09:16:57,237 (__init__.py:1088 MainThread) ERROR - TeleBot: "Threaded polling exception: A request to the Telegram API was unsuccessful. Error code: 409. Description: Conflict: terminated by other getUpdates request; make sure that only one bot instance is running"
2023-12-31 09:16:57,237 (__init__.py:1090 MainThread) ERROR - TeleBot: "Exception traceback:
Traceback (most recent call last):
  File "/usr/local/lib/python3.10/dist-packages/telebot/__init__.py", line 1081, in __threaded_polling
    polling_thread.raise_exceptions()
  File "/usr/local/lib/python3.10/dist-packages/telebot/util.py", line 108, in raise_exceptions
    raise self.exception_info
  File "/usr/local/lib/python3.10/dist-packages/telebot/util.py", line 90, in run
    task(*args, **kwargs)
  File "/usr/local/lib/python3.10/dist-packages/telebot/__init__.py", line 651, in __retrieve_updates
    updates = self.get_updates(offset=(self.last_update_id + 1),
  File "/usr/local/lib/python3.10/dist-packages/telebot/__init__.py", line 625, in get_updates
    json_updates = apihelper.get_updates(self.token, offset, limit, timeout, allowed_updates, long_polling_timeout)
  File "/usr/local/lib/python3.10/dist-packages/telebot/apihelper.py", line 323, in get_updates
    return _make_request(token, method_url, params=payload)
  File "/usr/local/lib/python3.10/dist-packages/telebot/apihelper.py", line 164, in _make_request
    json_result = _check_result(method_name, result)
  File "/usr/local/lib/python3.10/dist-packages/telebot/apihelper.py", line 191, in _check_result
    raise ApiTelegramException(method_name, result, result_json)
telebot.apihelper.ApiTelegramException: A request to the Telegram API was unsuccessful. Error code: 409. Description: Conflict: terminated by other getUpdates request; make sure that only one bot instance is running
"
2023-12-31 09:17:00,791 (__init__.py:1088 MainThread) ERROR - TeleBot: "Threaded polling exception: A request to the Telegram API was unsuccessful. Error code: 409. Description: Conflict: terminated by other getUpdates request; make sure that only one bot instance is running"
2023-12-31 09:17:00,791 (__init__.py:1090 MainThread) ERROR - TeleBot: "Exception traceback:
Traceback (most recent call last):
  File "/usr/local/lib/python3.10/dist-packages/telebot/__init__.py", line 1081, in __threaded_polling
    polling_thread.raise_exceptions()
  File "/usr/local/lib/python3.10/dist-packages/telebot/util.py", line 108, in raise_exceptions
    raise self.exception_info
  File "/usr/local/lib/python3.10/dist-packages/telebot/util.py", line 90, in run
    task(*args, **kwargs)
  File "/usr/local/lib/python3.10/dist-packages/telebot/__init__.py", line 651, in __retrieve_updates
    updates = self.get_updates(offset=(self.last_update_id + 1),
  File "/usr/local/lib/python3.10/dist-packages/telebot/__init__.py", line 625, in get_updates
    json_updates = apihelper.get_updates(self.token, offset, limit, timeout, allowed_updates, long_polling_timeout)
  File "/usr/local/lib/python3.10/dist-packages/telebot/apihelper.py", line 323, in get_updates
    return _make_request(token, method_url, params=payload)
  File "/usr/local/lib/python3.10/dist-packages/telebot/apihelper.py", line 164, in _make_request
    json_result = _check_result(method_name, result)
  File "/usr/local/lib/python3.10/dist-packages/telebot/apihelper.py", line 191, in _check_result
    raise ApiTelegramException(method_name, result, result_json)
telebot.apihelper.ApiTelegramException: A request to the Telegram API was unsuccessful. Error code: 409. Description: Conflict: terminated by other getUpdates request; make sure that only one bot instance is running
"
2023-12-31 09:17:32,846 (__init__.py:1088 MainThread) ERROR - TeleBot: "Threaded polling exception: A request to the Telegram API was unsuccessful. Error code: 409. Description: Conflict: terminated by other getUpdates request; make sure that only one bot instance is running"
2023-12-31 09:17:32,847 (__init__.py:1090 MainThread) ERROR - TeleBot: "Exception traceback:
Traceback (most recent call last):
  File "/usr/local/lib/python3.10/dist-packages/telebot/__init__.py", line 1081, in __threaded_polling
    polling_thread.raise_exceptions()
  File "/usr/local/lib/python3.10/dist-packages/telebot/util.py", line 108, in raise_exceptions
    raise self.exception_info
  File "/usr/local/lib/python3.10/dist-packages/telebot/util.py", line 90, in run
    task(*args, **kwargs)
  File "/usr/local/lib/python3.10/dist-packages/telebot/__init__.py", line 651, in __retrieve_updates
    updates = self.get_updates(offset=(self.last_update_id + 1),
  File "/usr/local/lib/python3.10/dist-packages/telebot/__init__.py", line 625, in get_updates
    json_updates = apihelper.get_updates(self.token, offset, limit, timeout, allowed_updates, long_polling_timeout)
  File "/usr/local/lib/python3.10/dist-packages/telebot/apihelper.py", line 323, in get_updates
    return _make_request(token, method_url, params=payload)
  File "/usr/local/lib/python3.10/dist-packages/telebot/apihelper.py", line 164, in _make_request
    json_result = _check_result(method_name, result)
  File "/usr/local/lib/python3.10/dist-packages/telebot/apihelper.py", line 191, in _check_result
    raise ApiTelegramException(method_name, result, result_json)
telebot.apihelper.ApiTelegramException: A request to the Telegram API was unsuccessful. Error code: 409. Description: Conflict: terminated by other getUpdates request; make sure that only one bot instance is running
"
2023-12-31 09:17:36,167 (__init__.py:1088 MainThread) ERROR - TeleBot: "Threaded polling exception: A request to the Telegram API was unsuccessful. Error code: 409. Description: Conflict: terminated by other getUpdates request; make sure that only one bot instance is running"
2023-12-31 09:17:36,167 (__init__.py:1090 MainThread) ERROR - TeleBot: "Exception traceback:
Traceback (most recent call last):
  File "/usr/local/lib/python3.10/dist-packages/telebot/__init__.py", line 1081, in __threaded_polling
    polling_thread.raise_exceptions()
  File "/usr/local/lib/python3.10/dist-packages/telebot/util.py", line 108, in raise_exceptions
    raise self.exception_info
  File "/usr/local/lib/python3.10/dist-packages/telebot/util.py", line 90, in run
    task(*args, **kwargs)
  File "/usr/local/lib/python3.10/dist-packages/telebot/__init__.py", line 651, in __retrieve_updates
    updates = self.get_updates(offset=(self.last_update_id + 1),
  File "/usr/local/lib/python3.10/dist-packages/telebot/__init__.py", line 625, in get_updates
    json_updates = apihelper.get_updates(self.token, offset, limit, timeout, allowed_updates, long_polling_timeout)
  File "/usr/local/lib/python3.10/dist-packages/telebot/apihelper.py", line 323, in get_updates
    return _make_request(token, method_url, params=payload)
  File "/usr/local/lib/python3.10/dist-packages/telebot/apihelper.py", line 164, in _make_request
    json_result = _check_result(method_name, result)
  File "/usr/local/lib/python3.10/dist-packages/telebot/apihelper.py", line 191, in _check_result
    raise ApiTelegramException(method_name, result, result_json)
telebot.apihelper.ApiTelegramException: A request to the Telegram API was unsuccessful. Error code: 409. Description: Conflict: terminated by other getUpdates request; make sure that only one bot instance is running
"
2023-12-31 09:18:36,267 (__init__.py:1088 MainThread) ERROR - TeleBot: "Threaded polling exception: A request to the Telegram API was unsuccessful. Error code: 409. Description: Conflict: terminated by other getUpdates request; make sure that only one bot instance is running"
2023-12-31 09:18:36,267 (__init__.py:1090 MainThread) ERROR - TeleBot: "Exception traceback:
Traceback (most recent call last):
  File "/usr/local/lib/python3.10/dist-packages/telebot/__init__.py", line 1081, in __threaded_polling
    polling_thread.raise_exceptions()
  File "/usr/local/lib/python3.10/dist-packages/telebot/util.py", line 108, in raise_exceptions
    raise self.exception_info
  File "/usr/local/lib/python3.10/dist-packages/telebot/util.py", line 90, in run
    task(*args, **kwargs)
  File "/usr/local/lib/python3.10/dist-packages/telebot/__init__.py", line 651, in __retrieve_updates
    updates = self.get_updates(offset=(self.last_update_id + 1),
  File "/usr/local/lib/python3.10/dist-packages/telebot/__init__.py", line 625, in get_updates
    json_updates = apihelper.get_updates(self.token, offset, limit, timeout, allowed_updates, long_polling_timeout)
  File "/usr/local/lib/python3.10/dist-packages/telebot/apihelper.py", line 323, in get_updates
    return _make_request(token, method_url, params=payload)
  File "/usr/local/lib/python3.10/dist-packages/telebot/apihelper.py", line 164, in _make_request
    json_result = _check_result(method_name, result)
  File "/usr/local/lib/python3.10/dist-packages/telebot/apihelper.py", line 191, in _check_result
    raise ApiTelegramException(method_name, result, result_json)
telebot.apihelper.ApiTelegramException: A request to the Telegram API was unsuccessful. Error code: 409. Description: Conflict: terminated by other getUpdates request; make sure that only one bot instance is running
"
2023-12-31 09:18:39,574 (__init__.py:1088 MainThread) ERROR - TeleBot: "Threaded polling exception: A request to the Telegram API was unsuccessful. Error code: 409. Description: Conflict: terminated by other getUpdates request; make sure that only one bot instance is running"
2023-12-31 09:18:39,574 (__init__.py:1090 MainThread) ERROR - TeleBot: "Exception traceback:
Traceback (most recent call last):
  File "/usr/local/lib/python3.10/dist-packages/telebot/__init__.py", line 1081, in __threaded_polling
    polling_thread.raise_exceptions()
  File "/usr/local/lib/python3.10/dist-packages/telebot/util.py", line 108, in raise_exceptions
    raise self.exception_info
  File "/usr/local/lib/python3.10/dist-packages/telebot/util.py", line 90, in run
    task(*args, **kwargs)
  File "/usr/local/lib/python3.10/dist-packages/telebot/__init__.py", line 651, in __retrieve_updates
    updates = self.get_updates(offset=(self.last_update_id + 1),
  File "/usr/local/lib/python3.10/dist-packages/telebot/__init__.py", line 625, in get_updates
    json_updates = apihelper.get_updates(self.token, offset, limit, timeout, allowed_updates, long_polling_timeout)
  File "/usr/local/lib/python3.10/dist-packages/telebot/apihelper.py", line 323, in get_updates
    return _make_request(token, method_url, params=payload)
  File "/usr/local/lib/python3.10/dist-packages/telebot/apihelper.py", line 164, in _make_request
    json_result = _check_result(method_name, result)
  File "/usr/local/lib/python3.10/dist-packages/telebot/apihelper.py", line 191, in _check_result
    raise ApiTelegramException(method_name, result, result_json)
telebot.apihelper.ApiTelegramException: A request to the Telegram API was unsuccessful. Error code: 409. Description: Conflict: terminated by other getUpdates request; make sure that only one bot instance is running
"
2023-12-31 09:19:39,637 (__init__.py:1088 MainThread) ERROR - TeleBot: "Threaded polling exception: A request to the Telegram API was unsuccessful. Error code: 409. Description: Conflict: terminated by other getUpdates request; make sure that only one bot instance is running"
2023-12-31 09:19:39,638 (__init__.py:1090 MainThread) ERROR - TeleBot: "Exception traceback:
Traceback (most recent call last):
  File "/usr/local/lib/python3.10/dist-packages/telebot/__init__.py", line 1081, in __threaded_polling
    polling_thread.raise_exceptions()
  File "/usr/local/lib/python3.10/dist-packages/telebot/util.py", line 108, in raise_exceptions
    raise self.exception_info
  File "/usr/local/lib/python3.10/dist-packages/telebot/util.py", line 90, in run
    task(*args, **kwargs)
  File "/usr/local/lib/python3.10/dist-packages/telebot/__init__.py", line 651, in __retrieve_updates
    updates = self.get_updates(offset=(self.last_update_id + 1),
  File "/usr/local/lib/python3.10/dist-packages/telebot/__init__.py", line 625, in get_updates
    json_updates = apihelper.get_updates(self.token, offset, limit, timeout, allowed_updates, long_polling_timeout)
  File "/usr/local/lib/python3.10/dist-packages/telebot/apihelper.py", line 323, in get_updates
    return _make_request(token, method_url, params=payload)
  File "/usr/local/lib/python3.10/dist-packages/telebot/apihelper.py", line 164, in _make_request
    json_result = _check_result(method_name, result)
  File "/usr/local/lib/python3.10/dist-packages/telebot/apihelper.py", line 191, in _check_result
    raise ApiTelegramException(method_name, result, result_json)
telebot.apihelper.ApiTelegramException: A request to the Telegram API was unsuccessful. Error code: 409. Description: Conflict: terminated by other getUpdates request; make sure that only one bot instance is running
"
2023-12-31 09:19:42,945 (__init__.py:1088 MainThread) ERROR - TeleBot: "Threaded polling exception: A request to the Telegram API was unsuccessful. Error code: 409. Description: Conflict: terminated by other getUpdates request; make sure that only one bot instance is running"
2023-12-31 09:19:42,946 (__init__.py:1090 MainThread) ERROR - TeleBot: "Exception traceback:
Traceback (most recent call last):
  File "/usr/local/lib/python3.10/dist-packages/telebot/__init__.py", line 1081, in __threaded_polling
    polling_thread.raise_exceptions()
  File "/usr/local/lib/python3.10/dist-packages/telebot/util.py", line 108, in raise_exceptions
    raise self.exception_info
  File "/usr/local/lib/python3.10/dist-packages/telebot/util.py", line 90, in run
    task(*args, **kwargs)
  File "/usr/local/lib/python3.10/dist-packages/telebot/__init__.py", line 651, in __retrieve_updates
    updates = self.get_updates(offset=(self.last_update_id + 1),
  File "/usr/local/lib/python3.10/dist-packages/telebot/__init__.py", line 625, in get_updates
    json_updates = apihelper.get_updates(self.token, offset, limit, timeout, allowed_updates, long_polling_timeout)
  File "/usr/local/lib/python3.10/dist-packages/telebot/apihelper.py", line 323, in get_updates
    return _make_request(token, method_url, params=payload)
  File "/usr/local/lib/python3.10/dist-packages/telebot/apihelper.py", line 164, in _make_request
    json_result = _check_result(method_name, result)
  File "/usr/local/lib/python3.10/dist-packages/telebot/apihelper.py", line 191, in _check_result
    raise ApiTelegramException(method_name, result, result_json)
telebot.apihelper.ApiTelegramException: A request to the Telegram API was unsuccessful. Error code: 409. Description: Conflict: terminated by other getUpdates request; make sure that only one bot instance is running
"
2023-12-31 09:20:43,057 (__init__.py:1088 MainThread) ERROR - TeleBot: "Threaded polling exception: A request to the Telegram API was unsuccessful. Error code: 409. Description: Conflict: terminated by other getUpdates request; make sure that only one bot instance is running"
2023-12-31 09:20:43,057 (__init__.py:1090 MainThread) ERROR - TeleBot: "Exception traceback:
Traceback (most recent call last):
  File "/usr/local/lib/python3.10/dist-packages/telebot/__init__.py", line 1081, in __threaded_polling
    polling_thread.raise_exceptions()
  File "/usr/local/lib/python3.10/dist-packages/telebot/util.py", line 108, in raise_exceptions
    raise self.exception_info
  File "/usr/local/lib/python3.10/dist-packages/telebot/util.py", line 90, in run
    task(*args, **kwargs)
  File "/usr/local/lib/python3.10/dist-packages/telebot/__init__.py", line 651, in __retrieve_updates
    updates = self.get_updates(offset=(self.last_update_id + 1),
  File "/usr/local/lib/python3.10/dist-packages/telebot/__init__.py", line 625, in get_updates
    json_updates = apihelper.get_updates(self.token, offset, limit, timeout, allowed_updates, long_polling_timeout)
  File "/usr/local/lib/python3.10/dist-packages/telebot/apihelper.py", line 323, in get_updates
    return _make_request(token, method_url, params=payload)
  File "/usr/local/lib/python3.10/dist-packages/telebot/apihelper.py", line 164, in _make_request
    json_result = _check_result(method_name, result)
  File "/usr/local/lib/python3.10/dist-packages/telebot/apihelper.py", line 191, in _check_result
    raise ApiTelegramException(method_name, result, result_json)
telebot.apihelper.ApiTelegramException: A request to the Telegram API was unsuccessful. Error code: 409. Description: Conflict: terminated by other getUpdates request; make sure that only one bot instance is running
"
2023-12-31 09:20:46,364 (__init__.py:1088 MainThread) ERROR - TeleBot: "Threaded polling exception: A request to the Telegram API was unsuccessful. Error code: 409. Description: Conflict: terminated by other getUpdates request; make sure that only one bot instance is running"
2023-12-31 09:20:46,364 (__init__.py:1090 MainThread) ERROR - TeleBot: "Exception traceback:
Traceback (most recent call last):
  File "/usr/local/lib/python3.10/dist-packages/telebot/__init__.py", line 1081, in __threaded_polling
    polling_thread.raise_exceptions()
  File "/usr/local/lib/python3.10/dist-packages/telebot/util.py", line 108, in raise_exceptions
    raise self.exception_info
  File "/usr/local/lib/python3.10/dist-packages/telebot/util.py", line 90, in run
    task(*args, **kwargs)
  File "/usr/local/lib/python3.10/dist-packages/telebot/__init__.py", line 651, in __retrieve_updates
    updates = self.get_updates(offset=(self.last_update_id + 1),
  File "/usr/local/lib/python3.10/dist-packages/telebot/__init__.py", line 625, in get_updates
    json_updates = apihelper.get_updates(self.token, offset, limit, timeout, allowed_updates, long_polling_timeout)
  File "/usr/local/lib/python3.10/dist-packages/telebot/apihelper.py", line 323, in get_updates
    return _make_request(token, method_url, params=payload)
  File "/usr/local/lib/python3.10/dist-packages/telebot/apihelper.py", line 164, in _make_request
    json_result = _check_result(method_name, result)
  File "/usr/local/lib/python3.10/dist-packages/telebot/apihelper.py", line 191, in _check_result
    raise ApiTelegramException(method_name, result, result_json)
telebot.apihelper.ApiTelegramException: A request to the Telegram API was unsuccessful. Error code: 409. Description: Conflict: terminated by other getUpdates request; make sure that only one bot instance is running
"
2023-12-31 09:21:46,479 (__init__.py:1088 MainThread) ERROR - TeleBot: "Threaded polling exception: A request to the Telegram API was unsuccessful. Error code: 409. Description: Conflict: terminated by other getUpdates request; make sure that only one bot instance is running"
2023-12-31 09:21:46,479 (__init__.py:1090 MainThread) ERROR - TeleBot: "Exception traceback:
Traceback (most recent call last):
  File "/usr/local/lib/python3.10/dist-packages/telebot/__init__.py", line 1081, in __threaded_polling
    polling_thread.raise_exceptions()
  File "/usr/local/lib/python3.10/dist-packages/telebot/util.py", line 108, in raise_exceptions
    raise self.exception_info
  File "/usr/local/lib/python3.10/dist-packages/telebot/util.py", line 90, in run
    task(*args, **kwargs)
  File "/usr/local/lib/python3.10/dist-packages/telebot/__init__.py", line 651, in __retrieve_updates
    updates = self.get_updates(offset=(self.last_update_id + 1),
  File "/usr/local/lib/python3.10/dist-packages/telebot/__init__.py", line 625, in get_updates
    json_updates = apihelper.get_updates(self.token, offset, limit, timeout, allowed_updates, long_polling_timeout)
  File "/usr/local/lib/python3.10/dist-packages/telebot/apihelper.py", line 323, in get_updates
    return _make_request(token, method_url, params=payload)
  File "/usr/local/lib/python3.10/dist-packages/telebot/apihelper.py", line 164, in _make_request
    json_result = _check_result(method_name, result)
  File "/usr/local/lib/python3.10/dist-packages/telebot/apihelper.py", line 191, in _check_result
    raise ApiTelegramException(method_name, result, result_json)
telebot.apihelper.ApiTelegramException: A request to the Telegram API was unsuccessful. Error code: 409. Description: Conflict: terminated by other getUpdates request; make sure that only one bot instance is running
"
2023-12-31 09:21:49,785 (__init__.py:1088 MainThread) ERROR - TeleBot: "Threaded polling exception: A request to the Telegram API was unsuccessful. Error code: 409. Description: Conflict: terminated by other getUpdates request; make sure that only one bot instance is running"
2023-12-31 09:21:49,785 (__init__.py:1090 MainThread) ERROR - TeleBot: "Exception traceback:
Traceback (most recent call last):
  File "/usr/local/lib/python3.10/dist-packages/telebot/__init__.py", line 1081, in __threaded_polling
    polling_thread.raise_exceptions()
  File "/usr/local/lib/python3.10/dist-packages/telebot/util.py", line 108, in raise_exceptions
    raise self.exception_info
  File "/usr/local/lib/python3.10/dist-packages/telebot/util.py", line 90, in run
    task(*args, **kwargs)
  File "/usr/local/lib/python3.10/dist-packages/telebot/__init__.py", line 651, in __retrieve_updates
    updates = self.get_updates(offset=(self.last_update_id + 1),
  File "/usr/local/lib/python3.10/dist-packages/telebot/__init__.py", line 625, in get_updates
    json_updates = apihelper.get_updates(self.token, offset, limit, timeout, allowed_updates, long_polling_timeout)
  File "/usr/local/lib/python3.10/dist-packages/telebot/apihelper.py", line 323, in get_updates
    return _make_request(token, method_url, params=payload)
  File "/usr/local/lib/python3.10/dist-packages/telebot/apihelper.py", line 164, in _make_request
    json_result = _check_result(method_name, result)
  File "/usr/local/lib/python3.10/dist-packages/telebot/apihelper.py", line 191, in _check_result
    raise ApiTelegramException(method_name, result, result_json)
telebot.apihelper.ApiTelegramException: A request to the Telegram API was unsuccessful. Error code: 409. Description: Conflict: terminated by other getUpdates request; make sure that only one bot instance is running
"
2023-12-31 09:22:49,870 (__init__.py:1088 MainThread) ERROR - TeleBot: "Threaded polling exception: A request to the Telegram API was unsuccessful. Error code: 409. Description: Conflict: terminated by other getUpdates request; make sure that only one bot instance is running"
2023-12-31 09:22:49,871 (__init__.py:1090 MainThread) ERROR - TeleBot: "Exception traceback:
Traceback (most recent call last):
  File "/usr/local/lib/python3.10/dist-packages/telebot/__init__.py", line 1081, in __threaded_polling
    polling_thread.raise_exceptions()
  File "/usr/local/lib/python3.10/dist-packages/telebot/util.py", line 108, in raise_exceptions
    raise self.exception_info
  File "/usr/local/lib/python3.10/dist-packages/telebot/util.py", line 90, in run
    task(*args, **kwargs)
  File "/usr/local/lib/python3.10/dist-packages/telebot/__init__.py", line 651, in __retrieve_updates
    updates = self.get_updates(offset=(self.last_update_id + 1),
  File "/usr/local/lib/python3.10/dist-packages/telebot/__init__.py", line 625, in get_updates
    json_updates = apihelper.get_updates(self.token, offset, limit, timeout, allowed_updates, long_polling_timeout)
  File "/usr/local/lib/python3.10/dist-packages/telebot/apihelper.py", line 323, in get_updates
    return _make_request(token, method_url, params=payload)
  File "/usr/local/lib/python3.10/dist-packages/telebot/apihelper.py", line 164, in _make_request
    json_result = _check_result(method_name, result)
  File "/usr/local/lib/python3.10/dist-packages/telebot/apihelper.py", line 191, in _check_result
    raise ApiTelegramException(method_name, result, result_json)
telebot.apihelper.ApiTelegramException: A request to the Telegram API was unsuccessful. Error code: 409. Description: Conflict: terminated by other getUpdates request; make sure that only one bot instance is running
"
2023-12-31 09:22:53,176 (__init__.py:1088 MainThread) ERROR - TeleBot: "Threaded polling exception: A request to the Telegram API was unsuccessful. Error code: 409. Description: Conflict: terminated by other getUpdates request; make sure that only one bot instance is running"
2023-12-31 09:22:53,176 (__init__.py:1090 MainThread) ERROR - TeleBot: "Exception traceback:
Traceback (most recent call last):
  File "/usr/local/lib/python3.10/dist-packages/telebot/__init__.py", line 1081, in __threaded_polling
    polling_thread.raise_exceptions()
  File "/usr/local/lib/python3.10/dist-packages/telebot/util.py", line 108, in raise_exceptions
    raise self.exception_info
  File "/usr/local/lib/python3.10/dist-packages/telebot/util.py", line 90, in run
    task(*args, **kwargs)
  File "/usr/local/lib/python3.10/dist-packages/telebot/__init__.py", line 651, in __retrieve_updates
    updates = self.get_updates(offset=(self.last_update_id + 1),
  File "/usr/local/lib/python3.10/dist-packages/telebot/__init__.py", line 625, in get_updates
    json_updates = apihelper.get_updates(self.token, offset, limit, timeout, allowed_updates, long_polling_timeout)
  File "/usr/local/lib/python3.10/dist-packages/telebot/apihelper.py", line 323, in get_updates
    return _make_request(token, method_url, params=payload)
  File "/usr/local/lib/python3.10/dist-packages/telebot/apihelper.py", line 164, in _make_request
    json_result = _check_result(method_name, result)
  File "/usr/local/lib/python3.10/dist-packages/telebot/apihelper.py", line 191, in _check_result
    raise ApiTelegramException(method_name, result, result_json)
telebot.apihelper.ApiTelegramException: A request to the Telegram API was unsuccessful. Error code: 409. Description: Conflict: terminated by other getUpdates request; make sure that only one bot instance is running
"
2023-12-31 09:23:53,293 (__init__.py:1088 MainThread) ERROR - TeleBot: "Threaded polling exception: A request to the Telegram API was unsuccessful. Error code: 409. Description: Conflict: terminated by other getUpdates request; make sure that only one bot instance is running"
2023-12-31 09:23:53,293 (__init__.py:1090 MainThread) ERROR - TeleBot: "Exception traceback:
Traceback (most recent call last):
  File "/usr/local/lib/python3.10/dist-packages/telebot/__init__.py", line 1081, in __threaded_polling
    polling_thread.raise_exceptions()
  File "/usr/local/lib/python3.10/dist-packages/telebot/util.py", line 108, in raise_exceptions
    raise self.exception_info
  File "/usr/local/lib/python3.10/dist-packages/telebot/util.py", line 90, in run
    task(*args, **kwargs)
  File "/usr/local/lib/python3.10/dist-packages/telebot/__init__.py", line 651, in __retrieve_updates
    updates = self.get_updates(offset=(self.last_update_id + 1),
  File "/usr/local/lib/python3.10/dist-packages/telebot/__init__.py", line 625, in get_updates
    json_updates = apihelper.get_updates(self.token, offset, limit, timeout, allowed_updates, long_polling_timeout)
  File "/usr/local/lib/python3.10/dist-packages/telebot/apihelper.py", line 323, in get_updates
    return _make_request(token, method_url, params=payload)
  File "/usr/local/lib/python3.10/dist-packages/telebot/apihelper.py", line 164, in _make_request
    json_result = _check_result(method_name, result)
  File "/usr/local/lib/python3.10/dist-packages/telebot/apihelper.py", line 191, in _check_result
    raise ApiTelegramException(method_name, result, result_json)
telebot.apihelper.ApiTelegramException: A request to the Telegram API was unsuccessful. Error code: 409. Description: Conflict: terminated by other getUpdates request; make sure that only one bot instance is running
"
2023-12-31 09:23:56,600 (__init__.py:1088 MainThread) ERROR - TeleBot: "Threaded polling exception: A request to the Telegram API was unsuccessful. Error code: 409. Description: Conflict: terminated by other getUpdates request; make sure that only one bot instance is running"
2023-12-31 09:23:56,600 (__init__.py:1090 MainThread) ERROR - TeleBot: "Exception traceback:
Traceback (most recent call last):
  File "/usr/local/lib/python3.10/dist-packages/telebot/__init__.py", line 1081, in __threaded_polling
    polling_thread.raise_exceptions()
  File "/usr/local/lib/python3.10/dist-packages/telebot/util.py", line 108, in raise_exceptions
    raise self.exception_info
  File "/usr/local/lib/python3.10/dist-packages/telebot/util.py", line 90, in run
    task(*args, **kwargs)
  File "/usr/local/lib/python3.10/dist-packages/telebot/__init__.py", line 651, in __retrieve_updates
    updates = self.get_updates(offset=(self.last_update_id + 1),
  File "/usr/local/lib/python3.10/dist-packages/telebot/__init__.py", line 625, in get_updates
    json_updates = apihelper.get_updates(self.token, offset, limit, timeout, allowed_updates, long_polling_timeout)
  File "/usr/local/lib/python3.10/dist-packages/telebot/apihelper.py", line 323, in get_updates
    return _make_request(token, method_url, params=payload)
  File "/usr/local/lib/python3.10/dist-packages/telebot/apihelper.py", line 164, in _make_request
    json_result = _check_result(method_name, result)
  File "/usr/local/lib/python3.10/dist-packages/telebot/apihelper.py", line 191, in _check_result
    raise ApiTelegramException(method_name, result, result_json)
telebot.apihelper.ApiTelegramException: A request to the Telegram API was unsuccessful. Error code: 409. Description: Conflict: terminated by other getUpdates request; make sure that only one bot instance is running
"
2023-12-31 09:24:56,671 (__init__.py:1088 MainThread) ERROR - TeleBot: "Threaded polling exception: A request to the Telegram API was unsuccessful. Error code: 409. Description: Conflict: terminated by other getUpdates request; make sure that only one bot instance is running"
2023-12-31 09:24:56,671 (__init__.py:1090 MainThread) ERROR - TeleBot: "Exception traceback:
Traceback (most recent call last):
  File "/usr/local/lib/python3.10/dist-packages/telebot/__init__.py", line 1081, in __threaded_polling
    polling_thread.raise_exceptions()
  File "/usr/local/lib/python3.10/dist-packages/telebot/util.py", line 108, in raise_exceptions
    raise self.exception_info
  File "/usr/local/lib/python3.10/dist-packages/telebot/util.py", line 90, in run
    task(*args, **kwargs)
  File "/usr/local/lib/python3.10/dist-packages/telebot/__init__.py", line 651, in __retrieve_updates
    updates = self.get_updates(offset=(self.last_update_id + 1),
  File "/usr/local/lib/python3.10/dist-packages/telebot/__init__.py", line 625, in get_updates
    json_updates = apihelper.get_updates(self.token, offset, limit, timeout, allowed_updates, long_polling_timeout)
  File "/usr/local/lib/python3.10/dist-packages/telebot/apihelper.py", line 323, in get_updates
    return _make_request(token, method_url, params=payload)
  File "/usr/local/lib/python3.10/dist-packages/telebot/apihelper.py", line 164, in _make_request
    json_result = _check_result(method_name, result)
  File "/usr/local/lib/python3.10/dist-packages/telebot/apihelper.py", line 191, in _check_result
    raise ApiTelegramException(method_name, result, result_json)
telebot.apihelper.ApiTelegramException: A request to the Telegram API was unsuccessful. Error code: 409. Description: Conflict: terminated by other getUpdates request; make sure that only one bot instance is running
"
2023-12-31 09:24:59,977 (__init__.py:1088 MainThread) ERROR - TeleBot: "Threaded polling exception: A request to the Telegram API was unsuccessful. Error code: 409. Description: Conflict: terminated by other getUpdates request; make sure that only one bot instance is running"
2023-12-31 09:24:59,977 (__init__.py:1090 MainThread) ERROR - TeleBot: "Exception traceback:
Traceback (most recent call last):
  File "/usr/local/lib/python3.10/dist-packages/telebot/__init__.py", line 1081, in __threaded_polling
    polling_thread.raise_exceptions()
  File "/usr/local/lib/python3.10/dist-packages/telebot/util.py", line 108, in raise_exceptions
    raise self.exception_info
  File "/usr/local/lib/python3.10/dist-packages/telebot/util.py", line 90, in run
    task(*args, **kwargs)
  File "/usr/local/lib/python3.10/dist-packages/telebot/__init__.py", line 651, in __retrieve_updates
    updates = self.get_updates(offset=(self.last_update_id + 1),
  File "/usr/local/lib/python3.10/dist-packages/telebot/__init__.py", line 625, in get_updates
    json_updates = apihelper.get_updates(self.token, offset, limit, timeout, allowed_updates, long_polling_timeout)
  File "/usr/local/lib/python3.10/dist-packages/telebot/apihelper.py", line 323, in get_updates
    return _make_request(token, method_url, params=payload)
  File "/usr/local/lib/python3.10/dist-packages/telebot/apihelper.py", line 164, in _make_request
    json_result = _check_result(method_name, result)
  File "/usr/local/lib/python3.10/dist-packages/telebot/apihelper.py", line 191, in _check_result
    raise ApiTelegramException(method_name, result, result_json)
telebot.apihelper.ApiTelegramException: A request to the Telegram API was unsuccessful. Error code: 409. Description: Conflict: terminated by other getUpdates request; make sure that only one bot instance is running
"
2023-12-31 09:26:00,415 (__init__.py:1088 MainThread) ERROR - TeleBot: "Threaded polling exception: A request to the Telegram API was unsuccessful. Error code: 409. Description: Conflict: terminated by other getUpdates request; make sure that only one bot instance is running"
2023-12-31 09:26:00,416 (__init__.py:1090 MainThread) ERROR - TeleBot: "Exception traceback:
Traceback (most recent call last):
  File "/usr/local/lib/python3.10/dist-packages/telebot/__init__.py", line 1081, in __threaded_polling
    polling_thread.raise_exceptions()
  File "/usr/local/lib/python3.10/dist-packages/telebot/util.py", line 108, in raise_exceptions
    raise self.exception_info
  File "/usr/local/lib/python3.10/dist-packages/telebot/util.py", line 90, in run
    task(*args, **kwargs)
  File "/usr/local/lib/python3.10/dist-packages/telebot/__init__.py", line 651, in __retrieve_updates
    updates = self.get_updates(offset=(self.last_update_id + 1),
  File "/usr/local/lib/python3.10/dist-packages/telebot/__init__.py", line 625, in get_updates
    json_updates = apihelper.get_updates(self.token, offset, limit, timeout, allowed_updates, long_polling_timeout)
  File "/usr/local/lib/python3.10/dist-packages/telebot/apihelper.py", line 323, in get_updates
    return _make_request(token, method_url, params=payload)
  File "/usr/local/lib/python3.10/dist-packages/telebot/apihelper.py", line 164, in _make_request
    json_result = _check_result(method_name, result)
  File "/usr/local/lib/python3.10/dist-packages/telebot/apihelper.py", line 191, in _check_result
    raise ApiTelegramException(method_name, result, result_json)
telebot.apihelper.ApiTelegramException: A request to the Telegram API was unsuccessful. Error code: 409. Description: Conflict: terminated by other getUpdates request; make sure that only one bot instance is running
"
2023-12-31 09:26:03,728 (__init__.py:1088 MainThread) ERROR - TeleBot: "Threaded polling exception: A request to the Telegram API was unsuccessful. Error code: 409. Description: Conflict: terminated by other getUpdates request; make sure that only one bot instance is running"
2023-12-31 09:26:03,728 (__init__.py:1090 MainThread) ERROR - TeleBot: "Exception traceback:
Traceback (most recent call last):
  File "/usr/local/lib/python3.10/dist-packages/telebot/__init__.py", line 1081, in __threaded_polling
    polling_thread.raise_exceptions()
  File "/usr/local/lib/python3.10/dist-packages/telebot/util.py", line 108, in raise_exceptions
    raise self.exception_info
  File "/usr/local/lib/python3.10/dist-packages/telebot/util.py", line 90, in run
    task(*args, **kwargs)
  File "/usr/local/lib/python3.10/dist-packages/telebot/__init__.py", line 651, in __retrieve_updates
    updates = self.get_updates(offset=(self.last_update_id + 1),
  File "/usr/local/lib/python3.10/dist-packages/telebot/__init__.py", line 625, in get_updates
    json_updates = apihelper.get_updates(self.token, offset, limit, timeout, allowed_updates, long_polling_timeout)
  File "/usr/local/lib/python3.10/dist-packages/telebot/apihelper.py", line 323, in get_updates
    return _make_request(token, method_url, params=payload)
  File "/usr/local/lib/python3.10/dist-packages/telebot/apihelper.py", line 164, in _make_request
    json_result = _check_result(method_name, result)
  File "/usr/local/lib/python3.10/dist-packages/telebot/apihelper.py", line 191, in _check_result
    raise ApiTelegramException(method_name, result, result_json)
telebot.apihelper.ApiTelegramException: A request to the Telegram API was unsuccessful. Error code: 409. Description: Conflict: terminated by other getUpdates request; make sure that only one bot instance is running
"
2023-12-31 09:27:03,825 (__init__.py:1088 MainThread) ERROR - TeleBot: "Threaded polling exception: A request to the Telegram API was unsuccessful. Error code: 409. Description: Conflict: terminated by other getUpdates request; make sure that only one bot instance is running"
2023-12-31 09:27:03,826 (__init__.py:1090 MainThread) ERROR - TeleBot: "Exception traceback:
Traceback (most recent call last):
  File "/usr/local/lib/python3.10/dist-packages/telebot/__init__.py", line 1081, in __threaded_polling
    polling_thread.raise_exceptions()
  File "/usr/local/lib/python3.10/dist-packages/telebot/util.py", line 108, in raise_exceptions
    raise self.exception_info
  File "/usr/local/lib/python3.10/dist-packages/telebot/util.py", line 90, in run
    task(*args, **kwargs)
  File "/usr/local/lib/python3.10/dist-packages/telebot/__init__.py", line 651, in __retrieve_updates
    updates = self.get_updates(offset=(self.last_update_id + 1),
  File "/usr/local/lib/python3.10/dist-packages/telebot/__init__.py", line 625, in get_updates
    json_updates = apihelper.get_updates(self.token, offset, limit, timeout, allowed_updates, long_polling_timeout)
  File "/usr/local/lib/python3.10/dist-packages/telebot/apihelper.py", line 323, in get_updates
    return _make_request(token, method_url, params=payload)
  File "/usr/local/lib/python3.10/dist-packages/telebot/apihelper.py", line 164, in _make_request
    json_result = _check_result(method_name, result)
  File "/usr/local/lib/python3.10/dist-packages/telebot/apihelper.py", line 191, in _check_result
    raise ApiTelegramException(method_name, result, result_json)
telebot.apihelper.ApiTelegramException: A request to the Telegram API was unsuccessful. Error code: 409. Description: Conflict: terminated by other getUpdates request; make sure that only one bot instance is running
"
2023-12-31 09:27:07,131 (__init__.py:1088 MainThread) ERROR - TeleBot: "Threaded polling exception: A request to the Telegram API was unsuccessful. Error code: 409. Description: Conflict: terminated by other getUpdates request; make sure that only one bot instance is running"
2023-12-31 09:27:07,131 (__init__.py:1090 MainThread) ERROR - TeleBot: "Exception traceback:
Traceback (most recent call last):
  File "/usr/local/lib/python3.10/dist-packages/telebot/__init__.py", line 1081, in __threaded_polling
    polling_thread.raise_exceptions()
  File "/usr/local/lib/python3.10/dist-packages/telebot/util.py", line 108, in raise_exceptions
    raise self.exception_info
  File "/usr/local/lib/python3.10/dist-packages/telebot/util.py", line 90, in run
    task(*args, **kwargs)
  File "/usr/local/lib/python3.10/dist-packages/telebot/__init__.py", line 651, in __retrieve_updates
    updates = self.get_updates(offset=(self.last_update_id + 1),
  File "/usr/local/lib/python3.10/dist-packages/telebot/__init__.py", line 625, in get_updates
    json_updates = apihelper.get_updates(self.token, offset, limit, timeout, allowed_updates, long_polling_timeout)
  File "/usr/local/lib/python3.10/dist-packages/telebot/apihelper.py", line 323, in get_updates
    return _make_request(token, method_url, params=payload)
  File "/usr/local/lib/python3.10/dist-packages/telebot/apihelper.py", line 164, in _make_request
    json_result = _check_result(method_name, result)
  File "/usr/local/lib/python3.10/dist-packages/telebot/apihelper.py", line 191, in _check_result
    raise ApiTelegramException(method_name, result, result_json)
telebot.apihelper.ApiTelegramException: A request to the Telegram API was unsuccessful. Error code: 409. Description: Conflict: terminated by other getUpdates request; make sure that only one bot instance is running
"
2023-12-31 09:28:07,254 (__init__.py:1088 MainThread) ERROR - TeleBot: "Threaded polling exception: A request to the Telegram API was unsuccessful. Error code: 409. Description: Conflict: terminated by other getUpdates request; make sure that only one bot instance is running"
2023-12-31 09:28:07,254 (__init__.py:1090 MainThread) ERROR - TeleBot: "Exception traceback:
Traceback (most recent call last):
  File "/usr/local/lib/python3.10/dist-packages/telebot/__init__.py", line 1081, in __threaded_polling
    polling_thread.raise_exceptions()
  File "/usr/local/lib/python3.10/dist-packages/telebot/util.py", line 108, in raise_exceptions
    raise self.exception_info
  File "/usr/local/lib/python3.10/dist-packages/telebot/util.py", line 90, in run
    task(*args, **kwargs)
  File "/usr/local/lib/python3.10/dist-packages/telebot/__init__.py", line 651, in __retrieve_updates
    updates = self.get_updates(offset=(self.last_update_id + 1),
  File "/usr/local/lib/python3.10/dist-packages/telebot/__init__.py", line 625, in get_updates
    json_updates = apihelper.get_updates(self.token, offset, limit, timeout, allowed_updates, long_polling_timeout)
  File "/usr/local/lib/python3.10/dist-packages/telebot/apihelper.py", line 323, in get_updates
    return _make_request(token, method_url, params=payload)
  File "/usr/local/lib/python3.10/dist-packages/telebot/apihelper.py", line 164, in _make_request
    json_result = _check_result(method_name, result)
  File "/usr/local/lib/python3.10/dist-packages/telebot/apihelper.py", line 191, in _check_result
    raise ApiTelegramException(method_name, result, result_json)
telebot.apihelper.ApiTelegramException: A request to the Telegram API was unsuccessful. Error code: 409. Description: Conflict: terminated by other getUpdates request; make sure that only one bot instance is running
"
2023-12-31 09:28:10,561 (__init__.py:1088 MainThread) ERROR - TeleBot: "Threaded polling exception: A request to the Telegram API was unsuccessful. Error code: 409. Description: Conflict: terminated by other getUpdates request; make sure that only one bot instance is running"
2023-12-31 09:28:10,561 (__init__.py:1090 MainThread) ERROR - TeleBot: "Exception traceback:
Traceback (most recent call last):
  File "/usr/local/lib/python3.10/dist-packages/telebot/__init__.py", line 1081, in __threaded_polling
    polling_thread.raise_exceptions()
  File "/usr/local/lib/python3.10/dist-packages/telebot/util.py", line 108, in raise_exceptions
    raise self.exception_info
  File "/usr/local/lib/python3.10/dist-packages/telebot/util.py", line 90, in run
    task(*args, **kwargs)
  File "/usr/local/lib/python3.10/dist-packages/telebot/__init__.py", line 651, in __retrieve_updates
    updates = self.get_updates(offset=(self.last_update_id + 1),
  File "/usr/local/lib/python3.10/dist-packages/telebot/__init__.py", line 625, in get_updates
    json_updates = apihelper.get_updates(self.token, offset, limit, timeout, allowed_updates, long_polling_timeout)
  File "/usr/local/lib/python3.10/dist-packages/telebot/apihelper.py", line 323, in get_updates
    return _make_request(token, method_url, params=payload)
  File "/usr/local/lib/python3.10/dist-packages/telebot/apihelper.py", line 164, in _make_request
    json_result = _check_result(method_name, result)
  File "/usr/local/lib/python3.10/dist-packages/telebot/apihelper.py", line 191, in _check_result
    raise ApiTelegramException(method_name, result, result_json)
telebot.apihelper.ApiTelegramException: A request to the Telegram API was unsuccessful. Error code: 409. Description: Conflict: terminated by other getUpdates request; make sure that only one bot instance is running
"
2023-12-31 09:29:11,042 (__init__.py:1088 MainThread) ERROR - TeleBot: "Threaded polling exception: A request to the Telegram API was unsuccessful. Error code: 409. Description: Conflict: terminated by other getUpdates request; make sure that only one bot instance is running"
2023-12-31 09:29:11,042 (__init__.py:1090 MainThread) ERROR - TeleBot: "Exception traceback:
Traceback (most recent call last):
  File "/usr/local/lib/python3.10/dist-packages/telebot/__init__.py", line 1081, in __threaded_polling
    polling_thread.raise_exceptions()
  File "/usr/local/lib/python3.10/dist-packages/telebot/util.py", line 108, in raise_exceptions
    raise self.exception_info
  File "/usr/local/lib/python3.10/dist-packages/telebot/util.py", line 90, in run
    task(*args, **kwargs)
  File "/usr/local/lib/python3.10/dist-packages/telebot/__init__.py", line 651, in __retrieve_updates
    updates = self.get_updates(offset=(self.last_update_id + 1),
  File "/usr/local/lib/python3.10/dist-packages/telebot/__init__.py", line 625, in get_updates
    json_updates = apihelper.get_updates(self.token, offset, limit, timeout, allowed_updates, long_polling_timeout)
  File "/usr/local/lib/python3.10/dist-packages/telebot/apihelper.py", line 323, in get_updates
    return _make_request(token, method_url, params=payload)
  File "/usr/local/lib/python3.10/dist-packages/telebot/apihelper.py", line 164, in _make_request
    json_result = _check_result(method_name, result)
  File "/usr/local/lib/python3.10/dist-packages/telebot/apihelper.py", line 191, in _check_result
    raise ApiTelegramException(method_name, result, result_json)
telebot.apihelper.ApiTelegramException: A request to the Telegram API was unsuccessful. Error code: 409. Description: Conflict: terminated by other getUpdates request; make sure that only one bot instance is running
"
2023-12-31 09:29:14,352 (__init__.py:1088 MainThread) ERROR - TeleBot: "Threaded polling exception: A request to the Telegram API was unsuccessful. Error code: 409. Description: Conflict: terminated by other getUpdates request; make sure that only one bot instance is running"
2023-12-31 09:29:14,353 (__init__.py:1090 MainThread) ERROR - TeleBot: "Exception traceback:
Traceback (most recent call last):
  File "/usr/local/lib/python3.10/dist-packages/telebot/__init__.py", line 1081, in __threaded_polling
    polling_thread.raise_exceptions()
  File "/usr/local/lib/python3.10/dist-packages/telebot/util.py", line 108, in raise_exceptions
    raise self.exception_info
  File "/usr/local/lib/python3.10/dist-packages/telebot/util.py", line 90, in run
    task(*args, **kwargs)
  File "/usr/local/lib/python3.10/dist-packages/telebot/__init__.py", line 651, in __retrieve_updates
    updates = self.get_updates(offset=(self.last_update_id + 1),
  File "/usr/local/lib/python3.10/dist-packages/telebot/__init__.py", line 625, in get_updates
    json_updates = apihelper.get_updates(self.token, offset, limit, timeout, allowed_updates, long_polling_timeout)
  File "/usr/local/lib/python3.10/dist-packages/telebot/apihelper.py", line 323, in get_updates
    return _make_request(token, method_url, params=payload)
  File "/usr/local/lib/python3.10/dist-packages/telebot/apihelper.py", line 164, in _make_request
    json_result = _check_result(method_name, result)
  File "/usr/local/lib/python3.10/dist-packages/telebot/apihelper.py", line 191, in _check_result
    raise ApiTelegramException(method_name, result, result_json)
telebot.apihelper.ApiTelegramException: A request to the Telegram API was unsuccessful. Error code: 409. Description: Conflict: terminated by other getUpdates request; make sure that only one bot instance is running
"
2023-12-31 09:30:14,469 (__init__.py:1088 MainThread) ERROR - TeleBot: "Threaded polling exception: A request to the Telegram API was unsuccessful. Error code: 409. Description: Conflict: terminated by other getUpdates request; make sure that only one bot instance is running"
2023-12-31 09:30:14,469 (__init__.py:1090 MainThread) ERROR - TeleBot: "Exception traceback:
Traceback (most recent call last):
  File "/usr/local/lib/python3.10/dist-packages/telebot/__init__.py", line 1081, in __threaded_polling
    polling_thread.raise_exceptions()
  File "/usr/local/lib/python3.10/dist-packages/telebot/util.py", line 108, in raise_exceptions
    raise self.exception_info
  File "/usr/local/lib/python3.10/dist-packages/telebot/util.py", line 90, in run
    task(*args, **kwargs)
  File "/usr/local/lib/python3.10/dist-packages/telebot/__init__.py", line 651, in __retrieve_updates
    updates = self.get_updates(offset=(self.last_update_id + 1),
  File "/usr/local/lib/python3.10/dist-packages/telebot/__init__.py", line 625, in get_updates
    json_updates = apihelper.get_updates(self.token, offset, limit, timeout, allowed_updates, long_polling_timeout)
  File "/usr/local/lib/python3.10/dist-packages/telebot/apihelper.py", line 323, in get_updates
    return _make_request(token, method_url, params=payload)
  File "/usr/local/lib/python3.10/dist-packages/telebot/apihelper.py", line 164, in _make_request
    json_result = _check_result(method_name, result)
  File "/usr/local/lib/python3.10/dist-packages/telebot/apihelper.py", line 191, in _check_result
    raise ApiTelegramException(method_name, result, result_json)
telebot.apihelper.ApiTelegramException: A request to the Telegram API was unsuccessful. Error code: 409. Description: Conflict: terminated by other getUpdates request; make sure that only one bot instance is running
"
2023-12-31 09:30:17,793 (__init__.py:1088 MainThread) ERROR - TeleBot: "Threaded polling exception: A request to the Telegram API was unsuccessful. Error code: 409. Description: Conflict: terminated by other getUpdates request; make sure that only one bot instance is running"
2023-12-31 09:30:17,794 (__init__.py:1090 MainThread) ERROR - TeleBot: "Exception traceback:
Traceback (most recent call last):
  File "/usr/local/lib/python3.10/dist-packages/telebot/__init__.py", line 1081, in __threaded_polling
    polling_thread.raise_exceptions()
  File "/usr/local/lib/python3.10/dist-packages/telebot/util.py", line 108, in raise_exceptions
    raise self.exception_info
  File "/usr/local/lib/python3.10/dist-packages/telebot/util.py", line 90, in run
    task(*args, **kwargs)
  File "/usr/local/lib/python3.10/dist-packages/telebot/__init__.py", line 651, in __retrieve_updates
    updates = self.get_updates(offset=(self.last_update_id + 1),
  File "/usr/local/lib/python3.10/dist-packages/telebot/__init__.py", line 625, in get_updates
    json_updates = apihelper.get_updates(self.token, offset, limit, timeout, allowed_updates, long_polling_timeout)
  File "/usr/local/lib/python3.10/dist-packages/telebot/apihelper.py", line 323, in get_updates
    return _make_request(token, method_url, params=payload)
  File "/usr/local/lib/python3.10/dist-packages/telebot/apihelper.py", line 164, in _make_request
    json_result = _check_result(method_name, result)
  File "/usr/local/lib/python3.10/dist-packages/telebot/apihelper.py", line 191, in _check_result
    raise ApiTelegramException(method_name, result, result_json)
telebot.apihelper.ApiTelegramException: A request to the Telegram API was unsuccessful. Error code: 409. Description: Conflict: terminated by other getUpdates request; make sure that only one bot instance is running
"
2023-12-31 09:31:17,942 (__init__.py:1088 MainThread) ERROR - TeleBot: "Threaded polling exception: A request to the Telegram API was unsuccessful. Error code: 409. Description: Conflict: terminated by other getUpdates request; make sure that only one bot instance is running"
2023-12-31 09:31:17,942 (__init__.py:1090 MainThread) ERROR - TeleBot: "Exception traceback:
Traceback (most recent call last):
  File "/usr/local/lib/python3.10/dist-packages/telebot/__init__.py", line 1081, in __threaded_polling
    polling_thread.raise_exceptions()
  File "/usr/local/lib/python3.10/dist-packages/telebot/util.py", line 108, in raise_exceptions
    raise self.exception_info
  File "/usr/local/lib/python3.10/dist-packages/telebot/util.py", line 90, in run
    task(*args, **kwargs)
  File "/usr/local/lib/python3.10/dist-packages/telebot/__init__.py", line 651, in __retrieve_updates
    updates = self.get_updates(offset=(self.last_update_id + 1),
  File "/usr/local/lib/python3.10/dist-packages/telebot/__init__.py", line 625, in get_updates
    json_updates = apihelper.get_updates(self.token, offset, limit, timeout, allowed_updates, long_polling_timeout)
  File "/usr/local/lib/python3.10/dist-packages/telebot/apihelper.py", line 323, in get_updates
    return _make_request(token, method_url, params=payload)
  File "/usr/local/lib/python3.10/dist-packages/telebot/apihelper.py", line 164, in _make_request
    json_result = _check_result(method_name, result)
  File "/usr/local/lib/python3.10/dist-packages/telebot/apihelper.py", line 191, in _check_result
    raise ApiTelegramException(method_name, result, result_json)
telebot.apihelper.ApiTelegramException: A request to the Telegram API was unsuccessful. Error code: 409. Description: Conflict: terminated by other getUpdates request; make sure that only one bot instance is running
"
2023-12-31 09:31:21,250 (__init__.py:1088 MainThread) ERROR - TeleBot: "Threaded polling exception: A request to the Telegram API was unsuccessful. Error code: 409. Description: Conflict: terminated by other getUpdates request; make sure that only one bot instance is running"
2023-12-31 09:31:21,250 (__init__.py:1090 MainThread) ERROR - TeleBot: "Exception traceback:
Traceback (most recent call last):
  File "/usr/local/lib/python3.10/dist-packages/telebot/__init__.py", line 1081, in __threaded_polling
    polling_thread.raise_exceptions()
  File "/usr/local/lib/python3.10/dist-packages/telebot/util.py", line 108, in raise_exceptions
    raise self.exception_info
  File "/usr/local/lib/python3.10/dist-packages/telebot/util.py", line 90, in run
    task(*args, **kwargs)
  File "/usr/local/lib/python3.10/dist-packages/telebot/__init__.py", line 651, in __retrieve_updates
    updates = self.get_updates(offset=(self.last_update_id + 1),
  File "/usr/local/lib/python3.10/dist-packages/telebot/__init__.py", line 625, in get_updates
    json_updates = apihelper.get_updates(self.token, offset, limit, timeout, allowed_updates, long_polling_timeout)
  File "/usr/local/lib/python3.10/dist-packages/telebot/apihelper.py", line 323, in get_updates
    return _make_request(token, method_url, params=payload)
  File "/usr/local/lib/python3.10/dist-packages/telebot/apihelper.py", line 164, in _make_request
    json_result = _check_result(method_name, result)
  File "/usr/local/lib/python3.10/dist-packages/telebot/apihelper.py", line 191, in _check_result
    raise ApiTelegramException(method_name, result, result_json)
telebot.apihelper.ApiTelegramException: A request to the Telegram API was unsuccessful. Error code: 409. Description: Conflict: terminated by other getUpdates request; make sure that only one bot instance is running
"
2023-12-31 09:31:46,524 (__init__.py:1088 MainThread) ERROR - TeleBot: "Threaded polling exception: A request to the Telegram API was unsuccessful. Error code: 409. Description: Conflict: terminated by other getUpdates request; make sure that only one bot instance is running"
2023-12-31 09:31:46,524 (__init__.py:1090 MainThread) ERROR - TeleBot: "Exception traceback:
Traceback (most recent call last):
  File "/usr/local/lib/python3.10/dist-packages/telebot/__init__.py", line 1081, in __threaded_polling
    polling_thread.raise_exceptions()
  File "/usr/local/lib/python3.10/dist-packages/telebot/util.py", line 108, in raise_exceptions
    raise self.exception_info
  File "/usr/local/lib/python3.10/dist-packages/telebot/util.py", line 90, in run
    task(*args, **kwargs)
  File "/usr/local/lib/python3.10/dist-packages/telebot/__init__.py", line 651, in __retrieve_updates
    updates = self.get_updates(offset=(self.last_update_id + 1),
  File "/usr/local/lib/python3.10/dist-packages/telebot/__init__.py", line 625, in get_updates
    json_updates = apihelper.get_updates(self.token, offset, limit, timeout, allowed_updates, long_polling_timeout)
  File "/usr/local/lib/python3.10/dist-packages/telebot/apihelper.py", line 323, in get_updates
    return _make_request(token, method_url, params=payload)
  File "/usr/local/lib/python3.10/dist-packages/telebot/apihelper.py", line 164, in _make_request
    json_result = _check_result(method_name, result)
  File "/usr/local/lib/python3.10/dist-packages/telebot/apihelper.py", line 191, in _check_result
    raise ApiTelegramException(method_name, result, result_json)
telebot.apihelper.ApiTelegramException: A request to the Telegram API was unsuccessful. Error code: 409. Description: Conflict: terminated by other getUpdates request; make sure that only one bot instance is running
"
2023-12-31 09:31:50,172 (__init__.py:1088 MainThread) ERROR - TeleBot: "Threaded polling exception: A request to the Telegram API was unsuccessful. Error code: 409. Description: Conflict: terminated by other getUpdates request; make sure that only one bot instance is running"
2023-12-31 09:31:50,172 (__init__.py:1090 MainThread) ERROR - TeleBot: "Exception traceback:
Traceback (most recent call last):
  File "/usr/local/lib/python3.10/dist-packages/telebot/__init__.py", line 1081, in __threaded_polling
    polling_thread.raise_exceptions()
  File "/usr/local/lib/python3.10/dist-packages/telebot/util.py", line 108, in raise_exceptions
    raise self.exception_info
  File "/usr/local/lib/python3.10/dist-packages/telebot/util.py", line 90, in run
    task(*args, **kwargs)
  File "/usr/local/lib/python3.10/dist-packages/telebot/__init__.py", line 651, in __retrieve_updates
    updates = self.get_updates(offset=(self.last_update_id + 1),
  File "/usr/local/lib/python3.10/dist-packages/telebot/__init__.py", line 625, in get_updates
    json_updates = apihelper.get_updates(self.token, offset, limit, timeout, allowed_updates, long_polling_timeout)
  File "/usr/local/lib/python3.10/dist-packages/telebot/apihelper.py", line 323, in get_updates
    return _make_request(token, method_url, params=payload)
  File "/usr/local/lib/python3.10/dist-packages/telebot/apihelper.py", line 164, in _make_request
    json_result = _check_result(method_name, result)
  File "/usr/local/lib/python3.10/dist-packages/telebot/apihelper.py", line 191, in _check_result
    raise ApiTelegramException(method_name, result, result_json)
telebot.apihelper.ApiTelegramException: A request to the Telegram API was unsuccessful. Error code: 409. Description: Conflict: terminated by other getUpdates request; make sure that only one bot instance is running
"
2023-12-31 09:31:54,308 (__init__.py:1088 MainThread) ERROR - TeleBot: "Threaded polling exception: A request to the Telegram API was unsuccessful. Error code: 409. Description: Conflict: terminated by other getUpdates request; make sure that only one bot instance is running"
2023-12-31 09:31:54,308 (__init__.py:1090 MainThread) ERROR - TeleBot: "Exception traceback:
Traceback (most recent call last):
  File "/usr/local/lib/python3.10/dist-packages/telebot/__init__.py", line 1081, in __threaded_polling
    polling_thread.raise_exceptions()
  File "/usr/local/lib/python3.10/dist-packages/telebot/util.py", line 108, in raise_exceptions
    raise self.exception_info
  File "/usr/local/lib/python3.10/dist-packages/telebot/util.py", line 90, in run
    task(*args, **kwargs)
  File "/usr/local/lib/python3.10/dist-packages/telebot/__init__.py", line 651, in __retrieve_updates
    updates = self.get_updates(offset=(self.last_update_id + 1),
  File "/usr/local/lib/python3.10/dist-packages/telebot/__init__.py", line 625, in get_updates
    json_updates = apihelper.get_updates(self.token, offset, limit, timeout, allowed_updates, long_polling_timeout)
  File "/usr/local/lib/python3.10/dist-packages/telebot/apihelper.py", line 323, in get_updates
    return _make_request(token, method_url, params=payload)
  File "/usr/local/lib/python3.10/dist-packages/telebot/apihelper.py", line 164, in _make_request
    json_result = _check_result(method_name, result)
  File "/usr/local/lib/python3.10/dist-packages/telebot/apihelper.py", line 191, in _check_result
    raise ApiTelegramException(method_name, result, result_json)
telebot.apihelper.ApiTelegramException: A request to the Telegram API was unsuccessful. Error code: 409. Description: Conflict: terminated by other getUpdates request; make sure that only one bot instance is running
"
2023-12-31 09:31:59,449 (__init__.py:1088 MainThread) ERROR - TeleBot: "Threaded polling exception: A request to the Telegram API was unsuccessful. Error code: 409. Description: Conflict: terminated by other getUpdates request; make sure that only one bot instance is running"
2023-12-31 09:31:59,450 (__init__.py:1090 MainThread) ERROR - TeleBot: "Exception traceback:
Traceback (most recent call last):
  File "/usr/local/lib/python3.10/dist-packages/telebot/__init__.py", line 1081, in __threaded_polling
    polling_thread.raise_exceptions()
  File "/usr/local/lib/python3.10/dist-packages/telebot/util.py", line 108, in raise_exceptions
    raise self.exception_info
  File "/usr/local/lib/python3.10/dist-packages/telebot/util.py", line 90, in run
    task(*args, **kwargs)
  File "/usr/local/lib/python3.10/dist-packages/telebot/__init__.py", line 651, in __retrieve_updates
    updates = self.get_updates(offset=(self.last_update_id + 1),
  File "/usr/local/lib/python3.10/dist-packages/telebot/__init__.py", line 625, in get_updates
    json_updates = apihelper.get_updates(self.token, offset, limit, timeout, allowed_updates, long_polling_timeout)
  File "/usr/local/lib/python3.10/dist-packages/telebot/apihelper.py", line 323, in get_updates
    return _make_request(token, method_url, params=payload)
  File "/usr/local/lib/python3.10/dist-packages/telebot/apihelper.py", line 164, in _make_request
    json_result = _check_result(method_name, result)
  File "/usr/local/lib/python3.10/dist-packages/telebot/apihelper.py", line 191, in _check_result
    raise ApiTelegramException(method_name, result, result_json)
telebot.apihelper.ApiTelegramException: A request to the Telegram API was unsuccessful. Error code: 409. Description: Conflict: terminated by other getUpdates request; make sure that only one bot instance is running
"
2023-12-31 09:32:06,580 (__init__.py:1088 MainThread) ERROR - TeleBot: "Threaded polling exception: A request to the Telegram API was unsuccessful. Error code: 409. Description: Conflict: terminated by other getUpdates request; make sure that only one bot instance is running"
2023-12-31 09:32:06,580 (__init__.py:1090 MainThread) ERROR - TeleBot: "Exception traceback:
Traceback (most recent call last):
  File "/usr/local/lib/python3.10/dist-packages/telebot/__init__.py", line 1081, in __threaded_polling
    polling_thread.raise_exceptions()
  File "/usr/local/lib/python3.10/dist-packages/telebot/util.py", line 108, in raise_exceptions
    raise self.exception_info
  File "/usr/local/lib/python3.10/dist-packages/telebot/util.py", line 90, in run
    task(*args, **kwargs)
  File "/usr/local/lib/python3.10/dist-packages/telebot/__init__.py", line 651, in __retrieve_updates
    updates = self.get_updates(offset=(self.last_update_id + 1),
  File "/usr/local/lib/python3.10/dist-packages/telebot/__init__.py", line 625, in get_updates
    json_updates = apihelper.get_updates(self.token, offset, limit, timeout, allowed_updates, long_polling_timeout)
  File "/usr/local/lib/python3.10/dist-packages/telebot/apihelper.py", line 323, in get_updates
    return _make_request(token, method_url, params=payload)
  File "/usr/local/lib/python3.10/dist-packages/telebot/apihelper.py", line 164, in _make_request
    json_result = _check_result(method_name, result)
  File "/usr/local/lib/python3.10/dist-packages/telebot/apihelper.py", line 191, in _check_result
    raise ApiTelegramException(method_name, result, result_json)
telebot.apihelper.ApiTelegramException: A request to the Telegram API was unsuccessful. Error code: 409. Description: Conflict: terminated by other getUpdates request; make sure that only one bot instance is running
"
2023-12-31 09:32:14,718 (__init__.py:1088 MainThread) ERROR - TeleBot: "Threaded polling exception: A request to the Telegram API was unsuccessful. Error code: 409. Description: Conflict: terminated by other getUpdates request; make sure that only one bot instance is running"
2023-12-31 09:32:14,718 (__init__.py:1090 MainThread) ERROR - TeleBot: "Exception traceback:
Traceback (most recent call last):
  File "/usr/local/lib/python3.10/dist-packages/telebot/__init__.py", line 1081, in __threaded_polling
    polling_thread.raise_exceptions()
  File "/usr/local/lib/python3.10/dist-packages/telebot/util.py", line 108, in raise_exceptions
    raise self.exception_info
  File "/usr/local/lib/python3.10/dist-packages/telebot/util.py", line 90, in run
    task(*args, **kwargs)
  File "/usr/local/lib/python3.10/dist-packages/telebot/__init__.py", line 651, in __retrieve_updates
    updates = self.get_updates(offset=(self.last_update_id + 1),
  File "/usr/local/lib/python3.10/dist-packages/telebot/__init__.py", line 625, in get_updates
    json_updates = apihelper.get_updates(self.token, offset, limit, timeout, allowed_updates, long_polling_timeout)
  File "/usr/local/lib/python3.10/dist-packages/telebot/apihelper.py", line 323, in get_updates
    return _make_request(token, method_url, params=payload)
  File "/usr/local/lib/python3.10/dist-packages/telebot/apihelper.py", line 164, in _make_request
    json_result = _check_result(method_name, result)
  File "/usr/local/lib/python3.10/dist-packages/telebot/apihelper.py", line 191, in _check_result
    raise ApiTelegramException(method_name, result, result_json)
telebot.apihelper.ApiTelegramException: A request to the Telegram API was unsuccessful. Error code: 409. Description: Conflict: terminated by other getUpdates request; make sure that only one bot instance is running
"
2023-12-31 09:32:25,782 (__init__.py:1088 MainThread) ERROR - TeleBot: "Threaded polling exception: A request to the Telegram API was unsuccessful. Error code: 409. Description: Conflict: terminated by other getUpdates request; make sure that only one bot instance is running"
2023-12-31 09:32:25,783 (__init__.py:1090 MainThread) ERROR - TeleBot: "Exception traceback:
Traceback (most recent call last):
  File "/usr/local/lib/python3.10/dist-packages/telebot/__init__.py", line 1081, in __threaded_polling
    polling_thread.raise_exceptions()
  File "/usr/local/lib/python3.10/dist-packages/telebot/util.py", line 108, in raise_exceptions
    raise self.exception_info
  File "/usr/local/lib/python3.10/dist-packages/telebot/util.py", line 90, in run
    task(*args, **kwargs)
  File "/usr/local/lib/python3.10/dist-packages/telebot/__init__.py", line 651, in __retrieve_updates
    updates = self.get_updates(offset=(self.last_update_id + 1),
  File "/usr/local/lib/python3.10/dist-packages/telebot/__init__.py", line 625, in get_updates
    json_updates = apihelper.get_updates(self.token, offset, limit, timeout, allowed_updates, long_polling_timeout)
  File "/usr/local/lib/python3.10/dist-packages/telebot/apihelper.py", line 323, in get_updates
    return _make_request(token, method_url, params=payload)
  File "/usr/local/lib/python3.10/dist-packages/telebot/apihelper.py", line 164, in _make_request
    json_result = _check_result(method_name, result)
  File "/usr/local/lib/python3.10/dist-packages/telebot/apihelper.py", line 191, in _check_result
    raise ApiTelegramException(method_name, result, result_json)
telebot.apihelper.ApiTelegramException: A request to the Telegram API was unsuccessful. Error code: 409. Description: Conflict: terminated by other getUpdates request; make sure that only one bot instance is running
"
2023-12-31 09:32:29,439 (__init__.py:1088 MainThread) ERROR - TeleBot: "Threaded polling exception: A request to the Telegram API was unsuccessful. Error code: 409. Description: Conflict: terminated by other getUpdates request; make sure that only one bot instance is running"
2023-12-31 09:32:29,439 (__init__.py:1090 MainThread) ERROR - TeleBot: "Exception traceback:
Traceback (most recent call last):
  File "/usr/local/lib/python3.10/dist-packages/telebot/__init__.py", line 1081, in __threaded_polling
    polling_thread.raise_exceptions()
  File "/usr/local/lib/python3.10/dist-packages/telebot/util.py", line 108, in raise_exceptions
    raise self.exception_info
  File "/usr/local/lib/python3.10/dist-packages/telebot/util.py", line 90, in run
    task(*args, **kwargs)
  File "/usr/local/lib/python3.10/dist-packages/telebot/__init__.py", line 651, in __retrieve_updates
    updates = self.get_updates(offset=(self.last_update_id + 1),
  File "/usr/local/lib/python3.10/dist-packages/telebot/__init__.py", line 625, in get_updates
    json_updates = apihelper.get_updates(self.token, offset, limit, timeout, allowed_updates, long_polling_timeout)
  File "/usr/local/lib/python3.10/dist-packages/telebot/apihelper.py", line 323, in get_updates
    return _make_request(token, method_url, params=payload)
  File "/usr/local/lib/python3.10/dist-packages/telebot/apihelper.py", line 164, in _make_request
    json_result = _check_result(method_name, result)
  File "/usr/local/lib/python3.10/dist-packages/telebot/apihelper.py", line 191, in _check_result
    raise ApiTelegramException(method_name, result, result_json)
telebot.apihelper.ApiTelegramException: A request to the Telegram API was unsuccessful. Error code: 409. Description: Conflict: terminated by other getUpdates request; make sure that only one bot instance is running
"
2023-12-31 09:33:01,598 (__init__.py:1088 MainThread) ERROR - TeleBot: "Threaded polling exception: A request to the Telegram API was unsuccessful. Error code: 409. Description: Conflict: terminated by other getUpdates request; make sure that only one bot instance is running"
2023-12-31 09:33:01,599 (__init__.py:1090 MainThread) ERROR - TeleBot: "Exception traceback:
Traceback (most recent call last):
  File "/usr/local/lib/python3.10/dist-packages/telebot/__init__.py", line 1081, in __threaded_polling
    polling_thread.raise_exceptions()
  File "/usr/local/lib/python3.10/dist-packages/telebot/util.py", line 108, in raise_exceptions
    raise self.exception_info
  File "/usr/local/lib/python3.10/dist-packages/telebot/util.py", line 90, in run
    task(*args, **kwargs)
  File "/usr/local/lib/python3.10/dist-packages/telebot/__init__.py", line 651, in __retrieve_updates
    updates = self.get_updates(offset=(self.last_update_id + 1),
  File "/usr/local/lib/python3.10/dist-packages/telebot/__init__.py", line 625, in get_updates
    json_updates = apihelper.get_updates(self.token, offset, limit, timeout, allowed_updates, long_polling_timeout)
  File "/usr/local/lib/python3.10/dist-packages/telebot/apihelper.py", line 323, in get_updates
    return _make_request(token, method_url, params=payload)
  File "/usr/local/lib/python3.10/dist-packages/telebot/apihelper.py", line 164, in _make_request
    json_result = _check_result(method_name, result)
  File "/usr/local/lib/python3.10/dist-packages/telebot/apihelper.py", line 191, in _check_result
    raise ApiTelegramException(method_name, result, result_json)
telebot.apihelper.ApiTelegramException: A request to the Telegram API was unsuccessful. Error code: 409. Description: Conflict: terminated by other getUpdates request; make sure that only one bot instance is running
"
2023-12-31 09:33:33,687 (__init__.py:1088 MainThread) ERROR - TeleBot: "Threaded polling exception: A request to the Telegram API was unsuccessful. Error code: 409. Description: Conflict: terminated by other getUpdates request; make sure that only one bot instance is running"
2023-12-31 09:33:33,687 (__init__.py:1090 MainThread) ERROR - TeleBot: "Exception traceback:
Traceback (most recent call last):
  File "/usr/local/lib/python3.10/dist-packages/telebot/__init__.py", line 1081, in __threaded_polling
    polling_thread.raise_exceptions()
  File "/usr/local/lib/python3.10/dist-packages/telebot/util.py", line 108, in raise_exceptions
    raise self.exception_info
  File "/usr/local/lib/python3.10/dist-packages/telebot/util.py", line 90, in run
    task(*args, **kwargs)
  File "/usr/local/lib/python3.10/dist-packages/telebot/__init__.py", line 651, in __retrieve_updates
    updates = self.get_updates(offset=(self.last_update_id + 1),
  File "/usr/local/lib/python3.10/dist-packages/telebot/__init__.py", line 625, in get_updates
    json_updates = apihelper.get_updates(self.token, offset, limit, timeout, allowed_updates, long_polling_timeout)
  File "/usr/local/lib/python3.10/dist-packages/telebot/apihelper.py", line 323, in get_updates
    return _make_request(token, method_url, params=payload)
  File "/usr/local/lib/python3.10/dist-packages/telebot/apihelper.py", line 164, in _make_request
    json_result = _check_result(method_name, result)
  File "/usr/local/lib/python3.10/dist-packages/telebot/apihelper.py", line 191, in _check_result
    raise ApiTelegramException(method_name, result, result_json)
telebot.apihelper.ApiTelegramException: A request to the Telegram API was unsuccessful. Error code: 409. Description: Conflict: terminated by other getUpdates request; make sure that only one bot instance is running
"
2023-12-31 09:34:33,766 (__init__.py:1088 MainThread) ERROR - TeleBot: "Threaded polling exception: A request to the Telegram API was unsuccessful. Error code: 409. Description: Conflict: terminated by other getUpdates request; make sure that only one bot instance is running"
2023-12-31 09:34:33,766 (__init__.py:1090 MainThread) ERROR - TeleBot: "Exception traceback:
Traceback (most recent call last):
  File "/usr/local/lib/python3.10/dist-packages/telebot/__init__.py", line 1081, in __threaded_polling
    polling_thread.raise_exceptions()
  File "/usr/local/lib/python3.10/dist-packages/telebot/util.py", line 108, in raise_exceptions
    raise self.exception_info
  File "/usr/local/lib/python3.10/dist-packages/telebot/util.py", line 90, in run
    task(*args, **kwargs)
  File "/usr/local/lib/python3.10/dist-packages/telebot/__init__.py", line 651, in __retrieve_updates
    updates = self.get_updates(offset=(self.last_update_id + 1),
  File "/usr/local/lib/python3.10/dist-packages/telebot/__init__.py", line 625, in get_updates
    json_updates = apihelper.get_updates(self.token, offset, limit, timeout, allowed_updates, long_polling_timeout)
  File "/usr/local/lib/python3.10/dist-packages/telebot/apihelper.py", line 323, in get_updates
    return _make_request(token, method_url, params=payload)
  File "/usr/local/lib/python3.10/dist-packages/telebot/apihelper.py", line 164, in _make_request
    json_result = _check_result(method_name, result)
  File "/usr/local/lib/python3.10/dist-packages/telebot/apihelper.py", line 191, in _check_result
    raise ApiTelegramException(method_name, result, result_json)
telebot.apihelper.ApiTelegramException: A request to the Telegram API was unsuccessful. Error code: 409. Description: Conflict: terminated by other getUpdates request; make sure that only one bot instance is running
"
2023-12-31 09:34:37,074 (__init__.py:1088 MainThread) ERROR - TeleBot: "Threaded polling exception: A request to the Telegram API was unsuccessful. Error code: 409. Description: Conflict: terminated by other getUpdates request; make sure that only one bot instance is running"
2023-12-31 09:34:37,074 (__init__.py:1090 MainThread) ERROR - TeleBot: "Exception traceback:
Traceback (most recent call last):
  File "/usr/local/lib/python3.10/dist-packages/telebot/__init__.py", line 1081, in __threaded_polling
    polling_thread.raise_exceptions()
  File "/usr/local/lib/python3.10/dist-packages/telebot/util.py", line 108, in raise_exceptions
    raise self.exception_info
  File "/usr/local/lib/python3.10/dist-packages/telebot/util.py", line 90, in run
    task(*args, **kwargs)
  File "/usr/local/lib/python3.10/dist-packages/telebot/__init__.py", line 651, in __retrieve_updates
    updates = self.get_updates(offset=(self.last_update_id + 1),
  File "/usr/local/lib/python3.10/dist-packages/telebot/__init__.py", line 625, in get_updates
    json_updates = apihelper.get_updates(self.token, offset, limit, timeout, allowed_updates, long_polling_timeout)
  File "/usr/local/lib/python3.10/dist-packages/telebot/apihelper.py", line 323, in get_updates
    return _make_request(token, method_url, params=payload)
  File "/usr/local/lib/python3.10/dist-packages/telebot/apihelper.py", line 164, in _make_request
    json_result = _check_result(method_name, result)
  File "/usr/local/lib/python3.10/dist-packages/telebot/apihelper.py", line 191, in _check_result
    raise ApiTelegramException(method_name, result, result_json)
telebot.apihelper.ApiTelegramException: A request to the Telegram API was unsuccessful. Error code: 409. Description: Conflict: terminated by other getUpdates request; make sure that only one bot instance is running
"
2023-12-31 09:34:39,060 (__init__.py:1088 MainThread) ERROR - TeleBot: "Threaded polling exception: A request to the Telegram API was unsuccessful. Error code: 409. Description: Conflict: terminated by other getUpdates request; make sure that only one bot instance is running"
2023-12-31 09:34:39,060 (__init__.py:1090 MainThread) ERROR - TeleBot: "Exception traceback:
Traceback (most recent call last):
  File "/usr/local/lib/python3.10/dist-packages/telebot/__init__.py", line 1081, in __threaded_polling
    polling_thread.raise_exceptions()
  File "/usr/local/lib/python3.10/dist-packages/telebot/util.py", line 108, in raise_exceptions
    raise self.exception_info
  File "/usr/local/lib/python3.10/dist-packages/telebot/util.py", line 90, in run
    task(*args, **kwargs)
  File "/usr/local/lib/python3.10/dist-packages/telebot/__init__.py", line 651, in __retrieve_updates
    updates = self.get_updates(offset=(self.last_update_id + 1),
  File "/usr/local/lib/python3.10/dist-packages/telebot/__init__.py", line 625, in get_updates
    json_updates = apihelper.get_updates(self.token, offset, limit, timeout, allowed_updates, long_polling_timeout)
  File "/usr/local/lib/python3.10/dist-packages/telebot/apihelper.py", line 323, in get_updates
    return _make_request(token, method_url, params=payload)
  File "/usr/local/lib/python3.10/dist-packages/telebot/apihelper.py", line 164, in _make_request
    json_result = _check_result(method_name, result)
  File "/usr/local/lib/python3.10/dist-packages/telebot/apihelper.py", line 191, in _check_result
    raise ApiTelegramException(method_name, result, result_json)
telebot.apihelper.ApiTelegramException: A request to the Telegram API was unsuccessful. Error code: 409. Description: Conflict: terminated by other getUpdates request; make sure that only one bot instance is running
"
2023-12-31 09:34:42,624 (__init__.py:1088 MainThread) ERROR - TeleBot: "Threaded polling exception: A request to the Telegram API was unsuccessful. Error code: 409. Description: Conflict: terminated by other getUpdates request; make sure that only one bot instance is running"
2023-12-31 09:34:42,624 (__init__.py:1090 MainThread) ERROR - TeleBot: "Exception traceback:
Traceback (most recent call last):
  File "/usr/local/lib/python3.10/dist-packages/telebot/__init__.py", line 1081, in __threaded_polling
    polling_thread.raise_exceptions()
  File "/usr/local/lib/python3.10/dist-packages/telebot/util.py", line 108, in raise_exceptions
    raise self.exception_info
  File "/usr/local/lib/python3.10/dist-packages/telebot/util.py", line 90, in run
    task(*args, **kwargs)
  File "/usr/local/lib/python3.10/dist-packages/telebot/__init__.py", line 651, in __retrieve_updates
    updates = self.get_updates(offset=(self.last_update_id + 1),
  File "/usr/local/lib/python3.10/dist-packages/telebot/__init__.py", line 625, in get_updates
    json_updates = apihelper.get_updates(self.token, offset, limit, timeout, allowed_updates, long_polling_timeout)
  File "/usr/local/lib/python3.10/dist-packages/telebot/apihelper.py", line 323, in get_updates
    return _make_request(token, method_url, params=payload)
  File "/usr/local/lib/python3.10/dist-packages/telebot/apihelper.py", line 164, in _make_request
    json_result = _check_result(method_name, result)
  File "/usr/local/lib/python3.10/dist-packages/telebot/apihelper.py", line 191, in _check_result
    raise ApiTelegramException(method_name, result, result_json)
telebot.apihelper.ApiTelegramException: A request to the Telegram API was unsuccessful. Error code: 409. Description: Conflict: terminated by other getUpdates request; make sure that only one bot instance is running
"
2023-12-31 09:34:42,932 (__init__.py:1088 MainThread) ERROR - TeleBot: "Threaded polling exception: A request to the Telegram API was unsuccessful. Error code: 409. Description: Conflict: terminated by other getUpdates request; make sure that only one bot instance is running"
2023-12-31 09:34:42,932 (__init__.py:1090 MainThread) ERROR - TeleBot: "Exception traceback:
Traceback (most recent call last):
  File "/usr/local/lib/python3.10/dist-packages/telebot/__init__.py", line 1081, in __threaded_polling
    polling_thread.raise_exceptions()
  File "/usr/local/lib/python3.10/dist-packages/telebot/util.py", line 108, in raise_exceptions
    raise self.exception_info
  File "/usr/local/lib/python3.10/dist-packages/telebot/util.py", line 90, in run
    task(*args, **kwargs)
  File "/usr/local/lib/python3.10/dist-packages/telebot/__init__.py", line 651, in __retrieve_updates
    updates = self.get_updates(offset=(self.last_update_id + 1),
  File "/usr/local/lib/python3.10/dist-packages/telebot/__init__.py", line 625, in get_updates
    json_updates = apihelper.get_updates(self.token, offset, limit, timeout, allowed_updates, long_polling_timeout)
  File "/usr/local/lib/python3.10/dist-packages/telebot/apihelper.py", line 323, in get_updates
    return _make_request(token, method_url, params=payload)
  File "/usr/local/lib/python3.10/dist-packages/telebot/apihelper.py", line 164, in _make_request
    json_result = _check_result(method_name, result)
  File "/usr/local/lib/python3.10/dist-packages/telebot/apihelper.py", line 191, in _check_result
    raise ApiTelegramException(method_name, result, result_json)
telebot.apihelper.ApiTelegramException: A request to the Telegram API was unsuccessful. Error code: 409. Description: Conflict: terminated by other getUpdates request; make sure that only one bot instance is running
"
2023-12-31 09:34:46,990 (__init__.py:1088 MainThread) ERROR - TeleBot: "Threaded polling exception: A request to the Telegram API was unsuccessful. Error code: 409. Description: Conflict: terminated by other getUpdates request; make sure that only one bot instance is running"
2023-12-31 09:34:46,990 (__init__.py:1090 MainThread) ERROR - TeleBot: "Exception traceback:
Traceback (most recent call last):
  File "/usr/local/lib/python3.10/dist-packages/telebot/__init__.py", line 1081, in __threaded_polling
    polling_thread.raise_exceptions()
  File "/usr/local/lib/python3.10/dist-packages/telebot/util.py", line 108, in raise_exceptions
    raise self.exception_info
  File "/usr/local/lib/python3.10/dist-packages/telebot/util.py", line 90, in run
    task(*args, **kwargs)
  File "/usr/local/lib/python3.10/dist-packages/telebot/__init__.py", line 651, in __retrieve_updates
    updates = self.get_updates(offset=(self.last_update_id + 1),
  File "/usr/local/lib/python3.10/dist-packages/telebot/__init__.py", line 625, in get_updates
    json_updates = apihelper.get_updates(self.token, offset, limit, timeout, allowed_updates, long_polling_timeout)
  File "/usr/local/lib/python3.10/dist-packages/telebot/apihelper.py", line 323, in get_updates
    return _make_request(token, method_url, params=payload)
  File "/usr/local/lib/python3.10/dist-packages/telebot/apihelper.py", line 164, in _make_request
    json_result = _check_result(method_name, result)
  File "/usr/local/lib/python3.10/dist-packages/telebot/apihelper.py", line 191, in _check_result
    raise ApiTelegramException(method_name, result, result_json)
telebot.apihelper.ApiTelegramException: A request to the Telegram API was unsuccessful. Error code: 409. Description: Conflict: terminated by other getUpdates request; make sure that only one bot instance is running
"
2023-12-31 09:34:47,555 (__init__.py:1088 MainThread) ERROR - TeleBot: "Threaded polling exception: A request to the Telegram API was unsuccessful. Error code: 409. Description: Conflict: terminated by other getUpdates request; make sure that only one bot instance is running"
2023-12-31 09:34:47,556 (__init__.py:1090 MainThread) ERROR - TeleBot: "Exception traceback:
Traceback (most recent call last):
  File "/usr/local/lib/python3.10/dist-packages/telebot/__init__.py", line 1081, in __threaded_polling
    polling_thread.raise_exceptions()
  File "/usr/local/lib/python3.10/dist-packages/telebot/util.py", line 108, in raise_exceptions
    raise self.exception_info
  File "/usr/local/lib/python3.10/dist-packages/telebot/util.py", line 90, in run
    task(*args, **kwargs)
  File "/usr/local/lib/python3.10/dist-packages/telebot/__init__.py", line 651, in __retrieve_updates
    updates = self.get_updates(offset=(self.last_update_id + 1),
  File "/usr/local/lib/python3.10/dist-packages/telebot/__init__.py", line 625, in get_updates
    json_updates = apihelper.get_updates(self.token, offset, limit, timeout, allowed_updates, long_polling_timeout)
  File "/usr/local/lib/python3.10/dist-packages/telebot/apihelper.py", line 323, in get_updates
    return _make_request(token, method_url, params=payload)
  File "/usr/local/lib/python3.10/dist-packages/telebot/apihelper.py", line 164, in _make_request
    json_result = _check_result(method_name, result)
  File "/usr/local/lib/python3.10/dist-packages/telebot/apihelper.py", line 191, in _check_result
    raise ApiTelegramException(method_name, result, result_json)
telebot.apihelper.ApiTelegramException: A request to the Telegram API was unsuccessful. Error code: 409. Description: Conflict: terminated by other getUpdates request; make sure that only one bot instance is running
"
2023-12-31 09:34:50,857 (__init__.py:1088 MainThread) ERROR - TeleBot: "Threaded polling exception: A request to the Telegram API was unsuccessful. Error code: 409. Description: Conflict: terminated by other getUpdates request; make sure that only one bot instance is running"
2023-12-31 09:34:50,858 (__init__.py:1090 MainThread) ERROR - TeleBot: "Exception traceback:
Traceback (most recent call last):
  File "/usr/local/lib/python3.10/dist-packages/telebot/__init__.py", line 1081, in __threaded_polling
    polling_thread.raise_exceptions()
  File "/usr/local/lib/python3.10/dist-packages/telebot/util.py", line 108, in raise_exceptions
    raise self.exception_info
  File "/usr/local/lib/python3.10/dist-packages/telebot/util.py", line 90, in run
    task(*args, **kwargs)
  File "/usr/local/lib/python3.10/dist-packages/telebot/__init__.py", line 651, in __retrieve_updates
    updates = self.get_updates(offset=(self.last_update_id + 1),
  File "/usr/local/lib/python3.10/dist-packages/telebot/__init__.py", line 625, in get_updates
    json_updates = apihelper.get_updates(self.token, offset, limit, timeout, allowed_updates, long_polling_timeout)
  File "/usr/local/lib/python3.10/dist-packages/telebot/apihelper.py", line 323, in get_updates
    return _make_request(token, method_url, params=payload)
  File "/usr/local/lib/python3.10/dist-packages/telebot/apihelper.py", line 164, in _make_request
    json_result = _check_result(method_name, result)
  File "/usr/local/lib/python3.10/dist-packages/telebot/apihelper.py", line 191, in _check_result
    raise ApiTelegramException(method_name, result, result_json)
telebot.apihelper.ApiTelegramException: A request to the Telegram API was unsuccessful. Error code: 409. Description: Conflict: terminated by other getUpdates request; make sure that only one bot instance is running
"
2023-12-31 09:34:51,915 (__init__.py:1088 MainThread) ERROR - TeleBot: "Threaded polling exception: A request to the Telegram API was unsuccessful. Error code: 409. Description: Conflict: terminated by other getUpdates request; make sure that only one bot instance is running"
2023-12-31 09:34:51,915 (__init__.py:1090 MainThread) ERROR - TeleBot: "Exception traceback:
Traceback (most recent call last):
  File "/usr/local/lib/python3.10/dist-packages/telebot/__init__.py", line 1081, in __threaded_polling
    polling_thread.raise_exceptions()
  File "/usr/local/lib/python3.10/dist-packages/telebot/util.py", line 108, in raise_exceptions
    raise self.exception_info
  File "/usr/local/lib/python3.10/dist-packages/telebot/util.py", line 90, in run
    task(*args, **kwargs)
  File "/usr/local/lib/python3.10/dist-packages/telebot/__init__.py", line 651, in __retrieve_updates
    updates = self.get_updates(offset=(self.last_update_id + 1),
  File "/usr/local/lib/python3.10/dist-packages/telebot/__init__.py", line 625, in get_updates
    json_updates = apihelper.get_updates(self.token, offset, limit, timeout, allowed_updates, long_polling_timeout)
  File "/usr/local/lib/python3.10/dist-packages/telebot/apihelper.py", line 323, in get_updates
    return _make_request(token, method_url, params=payload)
  File "/usr/local/lib/python3.10/dist-packages/telebot/apihelper.py", line 164, in _make_request
    json_result = _check_result(method_name, result)
  File "/usr/local/lib/python3.10/dist-packages/telebot/apihelper.py", line 191, in _check_result
    raise ApiTelegramException(method_name, result, result_json)
telebot.apihelper.ApiTelegramException: A request to the Telegram API was unsuccessful. Error code: 409. Description: Conflict: terminated by other getUpdates request; make sure that only one bot instance is running
"
2023-12-31 09:34:55,219 (__init__.py:1088 MainThread) ERROR - TeleBot: "Threaded polling exception: A request to the Telegram API was unsuccessful. Error code: 409. Description: Conflict: terminated by other getUpdates request; make sure that only one bot instance is running"
2023-12-31 09:34:55,219 (__init__.py:1090 MainThread) ERROR - TeleBot: "Exception traceback:
Traceback (most recent call last):
  File "/usr/local/lib/python3.10/dist-packages/telebot/__init__.py", line 1081, in __threaded_polling
    polling_thread.raise_exceptions()
  File "/usr/local/lib/python3.10/dist-packages/telebot/util.py", line 108, in raise_exceptions
    raise self.exception_info
  File "/usr/local/lib/python3.10/dist-packages/telebot/util.py", line 90, in run
    task(*args, **kwargs)
  File "/usr/local/lib/python3.10/dist-packages/telebot/__init__.py", line 651, in __retrieve_updates
    updates = self.get_updates(offset=(self.last_update_id + 1),
  File "/usr/local/lib/python3.10/dist-packages/telebot/__init__.py", line 625, in get_updates
    json_updates = apihelper.get_updates(self.token, offset, limit, timeout, allowed_updates, long_polling_timeout)
  File "/usr/local/lib/python3.10/dist-packages/telebot/apihelper.py", line 323, in get_updates
    return _make_request(token, method_url, params=payload)
  File "/usr/local/lib/python3.10/dist-packages/telebot/apihelper.py", line 164, in _make_request
    json_result = _check_result(method_name, result)
  File "/usr/local/lib/python3.10/dist-packages/telebot/apihelper.py", line 191, in _check_result
    raise ApiTelegramException(method_name, result, result_json)
telebot.apihelper.ApiTelegramException: A request to the Telegram API was unsuccessful. Error code: 409. Description: Conflict: terminated by other getUpdates request; make sure that only one bot instance is running
"
2023-12-31 09:34:57,278 (__init__.py:1088 MainThread) ERROR - TeleBot: "Threaded polling exception: A request to the Telegram API was unsuccessful. Error code: 409. Description: Conflict: terminated by other getUpdates request; make sure that only one bot instance is running"
2023-12-31 09:34:57,278 (__init__.py:1090 MainThread) ERROR - TeleBot: "Exception traceback:
Traceback (most recent call last):
  File "/usr/local/lib/python3.10/dist-packages/telebot/__init__.py", line 1081, in __threaded_polling
    polling_thread.raise_exceptions()
  File "/usr/local/lib/python3.10/dist-packages/telebot/util.py", line 108, in raise_exceptions
    raise self.exception_info
  File "/usr/local/lib/python3.10/dist-packages/telebot/util.py", line 90, in run
    task(*args, **kwargs)
  File "/usr/local/lib/python3.10/dist-packages/telebot/__init__.py", line 651, in __retrieve_updates
    updates = self.get_updates(offset=(self.last_update_id + 1),
  File "/usr/local/lib/python3.10/dist-packages/telebot/__init__.py", line 625, in get_updates
    json_updates = apihelper.get_updates(self.token, offset, limit, timeout, allowed_updates, long_polling_timeout)
  File "/usr/local/lib/python3.10/dist-packages/telebot/apihelper.py", line 323, in get_updates
    return _make_request(token, method_url, params=payload)
  File "/usr/local/lib/python3.10/dist-packages/telebot/apihelper.py", line 164, in _make_request
    json_result = _check_result(method_name, result)
  File "/usr/local/lib/python3.10/dist-packages/telebot/apihelper.py", line 191, in _check_result
    raise ApiTelegramException(method_name, result, result_json)
telebot.apihelper.ApiTelegramException: A request to the Telegram API was unsuccessful. Error code: 409. Description: Conflict: terminated by other getUpdates request; make sure that only one bot instance is running
"
2023-12-31 09:35:00,582 (__init__.py:1088 MainThread) ERROR - TeleBot: "Threaded polling exception: A request to the Telegram API was unsuccessful. Error code: 409. Description: Conflict: terminated by other getUpdates request; make sure that only one bot instance is running"
2023-12-31 09:35:00,582 (__init__.py:1090 MainThread) ERROR - TeleBot: "Exception traceback:
Traceback (most recent call last):
  File "/usr/local/lib/python3.10/dist-packages/telebot/__init__.py", line 1081, in __threaded_polling
    polling_thread.raise_exceptions()
  File "/usr/local/lib/python3.10/dist-packages/telebot/util.py", line 108, in raise_exceptions
    raise self.exception_info
  File "/usr/local/lib/python3.10/dist-packages/telebot/util.py", line 90, in run
    task(*args, **kwargs)
  File "/usr/local/lib/python3.10/dist-packages/telebot/__init__.py", line 651, in __retrieve_updates
    updates = self.get_updates(offset=(self.last_update_id + 1),
  File "/usr/local/lib/python3.10/dist-packages/telebot/__init__.py", line 625, in get_updates
    json_updates = apihelper.get_updates(self.token, offset, limit, timeout, allowed_updates, long_polling_timeout)
  File "/usr/local/lib/python3.10/dist-packages/telebot/apihelper.py", line 323, in get_updates
    return _make_request(token, method_url, params=payload)
  File "/usr/local/lib/python3.10/dist-packages/telebot/apihelper.py", line 164, in _make_request
    json_result = _check_result(method_name, result)
  File "/usr/local/lib/python3.10/dist-packages/telebot/apihelper.py", line 191, in _check_result
    raise ApiTelegramException(method_name, result, result_json)
telebot.apihelper.ApiTelegramException: A request to the Telegram API was unsuccessful. Error code: 409. Description: Conflict: terminated by other getUpdates request; make sure that only one bot instance is running
"
2023-12-31 09:35:04,650 (__init__.py:1088 MainThread) ERROR - TeleBot: "Threaded polling exception: A request to the Telegram API was unsuccessful. Error code: 409. Description: Conflict: terminated by other getUpdates request; make sure that only one bot instance is running"
2023-12-31 09:35:04,651 (__init__.py:1090 MainThread) ERROR - TeleBot: "Exception traceback:
Traceback (most recent call last):
  File "/usr/local/lib/python3.10/dist-packages/telebot/__init__.py", line 1081, in __threaded_polling
    polling_thread.raise_exceptions()
  File "/usr/local/lib/python3.10/dist-packages/telebot/util.py", line 108, in raise_exceptions
    raise self.exception_info
  File "/usr/local/lib/python3.10/dist-packages/telebot/util.py", line 90, in run
    task(*args, **kwargs)
  File "/usr/local/lib/python3.10/dist-packages/telebot/__init__.py", line 651, in __retrieve_updates
    updates = self.get_updates(offset=(self.last_update_id + 1),
  File "/usr/local/lib/python3.10/dist-packages/telebot/__init__.py", line 625, in get_updates
    json_updates = apihelper.get_updates(self.token, offset, limit, timeout, allowed_updates, long_polling_timeout)
  File "/usr/local/lib/python3.10/dist-packages/telebot/apihelper.py", line 323, in get_updates
    return _make_request(token, method_url, params=payload)
  File "/usr/local/lib/python3.10/dist-packages/telebot/apihelper.py", line 164, in _make_request
    json_result = _check_result(method_name, result)
  File "/usr/local/lib/python3.10/dist-packages/telebot/apihelper.py", line 191, in _check_result
    raise ApiTelegramException(method_name, result, result_json)
telebot.apihelper.ApiTelegramException: A request to the Telegram API was unsuccessful. Error code: 409. Description: Conflict: terminated by other getUpdates request; make sure that only one bot instance is running
"
2023-12-31 09:35:07,955 (__init__.py:1088 MainThread) ERROR - TeleBot: "Threaded polling exception: A request to the Telegram API was unsuccessful. Error code: 409. Description: Conflict: terminated by other getUpdates request; make sure that only one bot instance is running"
2023-12-31 09:35:07,955 (__init__.py:1090 MainThread) ERROR - TeleBot: "Exception traceback:
Traceback (most recent call last):
  File "/usr/local/lib/python3.10/dist-packages/telebot/__init__.py", line 1081, in __threaded_polling
    polling_thread.raise_exceptions()
  File "/usr/local/lib/python3.10/dist-packages/telebot/util.py", line 108, in raise_exceptions
    raise self.exception_info
  File "/usr/local/lib/python3.10/dist-packages/telebot/util.py", line 90, in run
    task(*args, **kwargs)
  File "/usr/local/lib/python3.10/dist-packages/telebot/__init__.py", line 651, in __retrieve_updates
    updates = self.get_updates(offset=(self.last_update_id + 1),
  File "/usr/local/lib/python3.10/dist-packages/telebot/__init__.py", line 625, in get_updates
    json_updates = apihelper.get_updates(self.token, offset, limit, timeout, allowed_updates, long_polling_timeout)
  File "/usr/local/lib/python3.10/dist-packages/telebot/apihelper.py", line 323, in get_updates
    return _make_request(token, method_url, params=payload)
  File "/usr/local/lib/python3.10/dist-packages/telebot/apihelper.py", line 164, in _make_request
    json_result = _check_result(method_name, result)
  File "/usr/local/lib/python3.10/dist-packages/telebot/apihelper.py", line 191, in _check_result
    raise ApiTelegramException(method_name, result, result_json)
telebot.apihelper.ApiTelegramException: A request to the Telegram API was unsuccessful. Error code: 409. Description: Conflict: terminated by other getUpdates request; make sure that only one bot instance is running
"
2023-12-31 09:35:16,019 (__init__.py:1088 MainThread) ERROR - TeleBot: "Threaded polling exception: A request to the Telegram API was unsuccessful. Error code: 409. Description: Conflict: terminated by other getUpdates request; make sure that only one bot instance is running"
2023-12-31 09:35:16,019 (__init__.py:1090 MainThread) ERROR - TeleBot: "Exception traceback:
Traceback (most recent call last):
  File "/usr/local/lib/python3.10/dist-packages/telebot/__init__.py", line 1081, in __threaded_polling
    polling_thread.raise_exceptions()
  File "/usr/local/lib/python3.10/dist-packages/telebot/util.py", line 108, in raise_exceptions
    raise self.exception_info
  File "/usr/local/lib/python3.10/dist-packages/telebot/util.py", line 90, in run
    task(*args, **kwargs)
  File "/usr/local/lib/python3.10/dist-packages/telebot/__init__.py", line 651, in __retrieve_updates
    updates = self.get_updates(offset=(self.last_update_id + 1),
  File "/usr/local/lib/python3.10/dist-packages/telebot/__init__.py", line 625, in get_updates
    json_updates = apihelper.get_updates(self.token, offset, limit, timeout, allowed_updates, long_polling_timeout)
  File "/usr/local/lib/python3.10/dist-packages/telebot/apihelper.py", line 323, in get_updates
    return _make_request(token, method_url, params=payload)
  File "/usr/local/lib/python3.10/dist-packages/telebot/apihelper.py", line 164, in _make_request
    json_result = _check_result(method_name, result)
  File "/usr/local/lib/python3.10/dist-packages/telebot/apihelper.py", line 191, in _check_result
    raise ApiTelegramException(method_name, result, result_json)
telebot.apihelper.ApiTelegramException: A request to the Telegram API was unsuccessful. Error code: 409. Description: Conflict: terminated by other getUpdates request; make sure that only one bot instance is running
"
2023-12-31 09:35:19,581 (__init__.py:1088 MainThread) ERROR - TeleBot: "Threaded polling exception: A request to the Telegram API was unsuccessful. Error code: 409. Description: Conflict: terminated by other getUpdates request; make sure that only one bot instance is running"
2023-12-31 09:35:19,581 (__init__.py:1090 MainThread) ERROR - TeleBot: "Exception traceback:
Traceback (most recent call last):
  File "/usr/local/lib/python3.10/dist-packages/telebot/__init__.py", line 1081, in __threaded_polling
    polling_thread.raise_exceptions()
  File "/usr/local/lib/python3.10/dist-packages/telebot/util.py", line 108, in raise_exceptions
    raise self.exception_info
  File "/usr/local/lib/python3.10/dist-packages/telebot/util.py", line 90, in run
    task(*args, **kwargs)
  File "/usr/local/lib/python3.10/dist-packages/telebot/__init__.py", line 651, in __retrieve_updates
    updates = self.get_updates(offset=(self.last_update_id + 1),
  File "/usr/local/lib/python3.10/dist-packages/telebot/__init__.py", line 625, in get_updates
    json_updates = apihelper.get_updates(self.token, offset, limit, timeout, allowed_updates, long_polling_timeout)
  File "/usr/local/lib/python3.10/dist-packages/telebot/apihelper.py", line 323, in get_updates
    return _make_request(token, method_url, params=payload)
  File "/usr/local/lib/python3.10/dist-packages/telebot/apihelper.py", line 164, in _make_request
    json_result = _check_result(method_name, result)
  File "/usr/local/lib/python3.10/dist-packages/telebot/apihelper.py", line 191, in _check_result
    raise ApiTelegramException(method_name, result, result_json)
telebot.apihelper.ApiTelegramException: A request to the Telegram API was unsuccessful. Error code: 409. Description: Conflict: terminated by other getUpdates request; make sure that only one bot instance is running
"
2023-12-31 09:35:35,655 (__init__.py:1088 MainThread) ERROR - TeleBot: "Threaded polling exception: A request to the Telegram API was unsuccessful. Error code: 409. Description: Conflict: terminated by other getUpdates request; make sure that only one bot instance is running"
2023-12-31 09:35:35,655 (__init__.py:1090 MainThread) ERROR - TeleBot: "Exception traceback:
Traceback (most recent call last):
  File "/usr/local/lib/python3.10/dist-packages/telebot/__init__.py", line 1081, in __threaded_polling
    polling_thread.raise_exceptions()
  File "/usr/local/lib/python3.10/dist-packages/telebot/util.py", line 108, in raise_exceptions
    raise self.exception_info
  File "/usr/local/lib/python3.10/dist-packages/telebot/util.py", line 90, in run
    task(*args, **kwargs)
  File "/usr/local/lib/python3.10/dist-packages/telebot/__init__.py", line 651, in __retrieve_updates
    updates = self.get_updates(offset=(self.last_update_id + 1),
  File "/usr/local/lib/python3.10/dist-packages/telebot/__init__.py", line 625, in get_updates
    json_updates = apihelper.get_updates(self.token, offset, limit, timeout, allowed_updates, long_polling_timeout)
  File "/usr/local/lib/python3.10/dist-packages/telebot/apihelper.py", line 323, in get_updates
    return _make_request(token, method_url, params=payload)
  File "/usr/local/lib/python3.10/dist-packages/telebot/apihelper.py", line 164, in _make_request
    json_result = _check_result(method_name, result)
  File "/usr/local/lib/python3.10/dist-packages/telebot/apihelper.py", line 191, in _check_result
    raise ApiTelegramException(method_name, result, result_json)
telebot.apihelper.ApiTelegramException: A request to the Telegram API was unsuccessful. Error code: 409. Description: Conflict: terminated by other getUpdates request; make sure that only one bot instance is running
"
2023-12-31 09:35:38,957 (__init__.py:1088 MainThread) ERROR - TeleBot: "Threaded polling exception: A request to the Telegram API was unsuccessful. Error code: 409. Description: Conflict: terminated by other getUpdates request; make sure that only one bot instance is running"
2023-12-31 09:35:38,958 (__init__.py:1090 MainThread) ERROR - TeleBot: "Exception traceback:
Traceback (most recent call last):
  File "/usr/local/lib/python3.10/dist-packages/telebot/__init__.py", line 1081, in __threaded_polling
    polling_thread.raise_exceptions()
  File "/usr/local/lib/python3.10/dist-packages/telebot/util.py", line 108, in raise_exceptions
    raise self.exception_info
  File "/usr/local/lib/python3.10/dist-packages/telebot/util.py", line 90, in run
    task(*args, **kwargs)
  File "/usr/local/lib/python3.10/dist-packages/telebot/__init__.py", line 651, in __retrieve_updates
    updates = self.get_updates(offset=(self.last_update_id + 1),
  File "/usr/local/lib/python3.10/dist-packages/telebot/__init__.py", line 625, in get_updates
    json_updates = apihelper.get_updates(self.token, offset, limit, timeout, allowed_updates, long_polling_timeout)
  File "/usr/local/lib/python3.10/dist-packages/telebot/apihelper.py", line 323, in get_updates
    return _make_request(token, method_url, params=payload)
  File "/usr/local/lib/python3.10/dist-packages/telebot/apihelper.py", line 164, in _make_request
    json_result = _check_result(method_name, result)
  File "/usr/local/lib/python3.10/dist-packages/telebot/apihelper.py", line 191, in _check_result
    raise ApiTelegramException(method_name, result, result_json)
telebot.apihelper.ApiTelegramException: A request to the Telegram API was unsuccessful. Error code: 409. Description: Conflict: terminated by other getUpdates request; make sure that only one bot instance is running
"
2023-12-31 09:35:40,189 (__init__.py:1088 MainThread) ERROR - TeleBot: "Threaded polling exception: A request to the Telegram API was unsuccessful. Error code: 409. Description: Conflict: terminated by other getUpdates request; make sure that only one bot instance is running"
2023-12-31 09:35:40,189 (__init__.py:1090 MainThread) ERROR - TeleBot: "Exception traceback:
Traceback (most recent call last):
  File "/usr/local/lib/python3.10/dist-packages/telebot/__init__.py", line 1081, in __threaded_polling
    polling_thread.raise_exceptions()
  File "/usr/local/lib/python3.10/dist-packages/telebot/util.py", line 108, in raise_exceptions
    raise self.exception_info
  File "/usr/local/lib/python3.10/dist-packages/telebot/util.py", line 90, in run
    task(*args, **kwargs)
  File "/usr/local/lib/python3.10/dist-packages/telebot/__init__.py", line 651, in __retrieve_updates
    updates = self.get_updates(offset=(self.last_update_id + 1),
  File "/usr/local/lib/python3.10/dist-packages/telebot/__init__.py", line 625, in get_updates
    json_updates = apihelper.get_updates(self.token, offset, limit, timeout, allowed_updates, long_polling_timeout)
  File "/usr/local/lib/python3.10/dist-packages/telebot/apihelper.py", line 323, in get_updates
    return _make_request(token, method_url, params=payload)
  File "/usr/local/lib/python3.10/dist-packages/telebot/apihelper.py", line 164, in _make_request
    json_result = _check_result(method_name, result)
  File "/usr/local/lib/python3.10/dist-packages/telebot/apihelper.py", line 191, in _check_result
    raise ApiTelegramException(method_name, result, result_json)
telebot.apihelper.ApiTelegramException: A request to the Telegram API was unsuccessful. Error code: 409. Description: Conflict: terminated by other getUpdates request; make sure that only one bot instance is running
"
2023-12-31 09:35:41,016 (__init__.py:1088 MainThread) ERROR - TeleBot: "Threaded polling exception: A request to the Telegram API was unsuccessful. Error code: 409. Description: Conflict: terminated by other getUpdates request; make sure that only one bot instance is running"
2023-12-31 09:35:41,016 (__init__.py:1090 MainThread) ERROR - TeleBot: "Exception traceback:
Traceback (most recent call last):
  File "/usr/local/lib/python3.10/dist-packages/telebot/__init__.py", line 1081, in __threaded_polling
    polling_thread.raise_exceptions()
  File "/usr/local/lib/python3.10/dist-packages/telebot/util.py", line 108, in raise_exceptions
    raise self.exception_info
  File "/usr/local/lib/python3.10/dist-packages/telebot/util.py", line 90, in run
    task(*args, **kwargs)
  File "/usr/local/lib/python3.10/dist-packages/telebot/__init__.py", line 651, in __retrieve_updates
    updates = self.get_updates(offset=(self.last_update_id + 1),
  File "/usr/local/lib/python3.10/dist-packages/telebot/__init__.py", line 625, in get_updates
    json_updates = apihelper.get_updates(self.token, offset, limit, timeout, allowed_updates, long_polling_timeout)
  File "/usr/local/lib/python3.10/dist-packages/telebot/apihelper.py", line 323, in get_updates
    return _make_request(token, method_url, params=payload)
  File "/usr/local/lib/python3.10/dist-packages/telebot/apihelper.py", line 164, in _make_request
    json_result = _check_result(method_name, result)
  File "/usr/local/lib/python3.10/dist-packages/telebot/apihelper.py", line 191, in _check_result
    raise ApiTelegramException(method_name, result, result_json)
telebot.apihelper.ApiTelegramException: A request to the Telegram API was unsuccessful. Error code: 409. Description: Conflict: terminated by other getUpdates request; make sure that only one bot instance is running
"
2023-12-31 09:36:11,029 (__init__.py:1088 MainThread) ERROR - TeleBot: "Threaded polling exception: A request to the Telegram API was unsuccessful. Error code: 409. Description: Conflict: terminated by other getUpdates request; make sure that only one bot instance is running"
2023-12-31 09:36:11,029 (__init__.py:1090 MainThread) ERROR - TeleBot: "Exception traceback:
Traceback (most recent call last):
  File "/usr/local/lib/python3.10/dist-packages/telebot/__init__.py", line 1081, in __threaded_polling
    polling_thread.raise_exceptions()
  File "/usr/local/lib/python3.10/dist-packages/telebot/util.py", line 108, in raise_exceptions
    raise self.exception_info
  File "/usr/local/lib/python3.10/dist-packages/telebot/util.py", line 90, in run
    task(*args, **kwargs)
  File "/usr/local/lib/python3.10/dist-packages/telebot/__init__.py", line 651, in __retrieve_updates
    updates = self.get_updates(offset=(self.last_update_id + 1),
  File "/usr/local/lib/python3.10/dist-packages/telebot/__init__.py", line 625, in get_updates
    json_updates = apihelper.get_updates(self.token, offset, limit, timeout, allowed_updates, long_polling_timeout)
  File "/usr/local/lib/python3.10/dist-packages/telebot/apihelper.py", line 323, in get_updates
    return _make_request(token, method_url, params=payload)
  File "/usr/local/lib/python3.10/dist-packages/telebot/apihelper.py", line 164, in _make_request
    json_result = _check_result(method_name, result)
  File "/usr/local/lib/python3.10/dist-packages/telebot/apihelper.py", line 191, in _check_result
    raise ApiTelegramException(method_name, result, result_json)
telebot.apihelper.ApiTelegramException: A request to the Telegram API was unsuccessful. Error code: 409. Description: Conflict: terminated by other getUpdates request; make sure that only one bot instance is running
"
2023-12-31 09:36:14,333 (__init__.py:1088 MainThread) ERROR - TeleBot: "Threaded polling exception: A request to the Telegram API was unsuccessful. Error code: 409. Description: Conflict: terminated by other getUpdates request; make sure that only one bot instance is running"
2023-12-31 09:36:14,333 (__init__.py:1090 MainThread) ERROR - TeleBot: "Exception traceback:
Traceback (most recent call last):
  File "/usr/local/lib/python3.10/dist-packages/telebot/__init__.py", line 1081, in __threaded_polling
    polling_thread.raise_exceptions()
  File "/usr/local/lib/python3.10/dist-packages/telebot/util.py", line 108, in raise_exceptions
    raise self.exception_info
  File "/usr/local/lib/python3.10/dist-packages/telebot/util.py", line 90, in run
    task(*args, **kwargs)
  File "/usr/local/lib/python3.10/dist-packages/telebot/__init__.py", line 651, in __retrieve_updates
    updates = self.get_updates(offset=(self.last_update_id + 1),
  File "/usr/local/lib/python3.10/dist-packages/telebot/__init__.py", line 625, in get_updates
    json_updates = apihelper.get_updates(self.token, offset, limit, timeout, allowed_updates, long_polling_timeout)
  File "/usr/local/lib/python3.10/dist-packages/telebot/apihelper.py", line 323, in get_updates
    return _make_request(token, method_url, params=payload)
  File "/usr/local/lib/python3.10/dist-packages/telebot/apihelper.py", line 164, in _make_request
    json_result = _check_result(method_name, result)
  File "/usr/local/lib/python3.10/dist-packages/telebot/apihelper.py", line 191, in _check_result
    raise ApiTelegramException(method_name, result, result_json)
telebot.apihelper.ApiTelegramException: A request to the Telegram API was unsuccessful. Error code: 409. Description: Conflict: terminated by other getUpdates request; make sure that only one bot instance is running
"
2023-12-31 09:36:41,405 (__init__.py:1088 MainThread) ERROR - TeleBot: "Threaded polling exception: A request to the Telegram API was unsuccessful. Error code: 409. Description: Conflict: terminated by other getUpdates request; make sure that only one bot instance is running"
2023-12-31 09:36:41,405 (__init__.py:1090 MainThread) ERROR - TeleBot: "Exception traceback:
Traceback (most recent call last):
  File "/usr/local/lib/python3.10/dist-packages/telebot/__init__.py", line 1081, in __threaded_polling
    polling_thread.raise_exceptions()
  File "/usr/local/lib/python3.10/dist-packages/telebot/util.py", line 108, in raise_exceptions
    raise self.exception_info
  File "/usr/local/lib/python3.10/dist-packages/telebot/util.py", line 90, in run
    task(*args, **kwargs)
  File "/usr/local/lib/python3.10/dist-packages/telebot/__init__.py", line 651, in __retrieve_updates
    updates = self.get_updates(offset=(self.last_update_id + 1),
  File "/usr/local/lib/python3.10/dist-packages/telebot/__init__.py", line 625, in get_updates
    json_updates = apihelper.get_updates(self.token, offset, limit, timeout, allowed_updates, long_polling_timeout)
  File "/usr/local/lib/python3.10/dist-packages/telebot/apihelper.py", line 323, in get_updates
    return _make_request(token, method_url, params=payload)
  File "/usr/local/lib/python3.10/dist-packages/telebot/apihelper.py", line 164, in _make_request
    json_result = _check_result(method_name, result)
  File "/usr/local/lib/python3.10/dist-packages/telebot/apihelper.py", line 191, in _check_result
    raise ApiTelegramException(method_name, result, result_json)
telebot.apihelper.ApiTelegramException: A request to the Telegram API was unsuccessful. Error code: 409. Description: Conflict: terminated by other getUpdates request; make sure that only one bot instance is running
"
2024-01-03 01:10:15,638 (__init__.py:1088 MainThread) ERROR - TeleBot: "Threaded polling exception: A request to the Telegram API was unsuccessful. Error code: 429. Description: Too Many Requests: retry after 5"
2024-01-03 01:10:15,639 (__init__.py:1090 MainThread) ERROR - TeleBot: "Exception traceback:
Traceback (most recent call last):
  File "/usr/local/lib/python3.10/dist-packages/telebot/__init__.py", line 1081, in __threaded_polling
    polling_thread.raise_exceptions()
  File "/usr/local/lib/python3.10/dist-packages/telebot/util.py", line 108, in raise_exceptions
    raise self.exception_info
  File "/usr/local/lib/python3.10/dist-packages/telebot/util.py", line 90, in run
    task(*args, **kwargs)
  File "/usr/local/lib/python3.10/dist-packages/telebot/__init__.py", line 651, in __retrieve_updates
    updates = self.get_updates(offset=(self.last_update_id + 1),
  File "/usr/local/lib/python3.10/dist-packages/telebot/__init__.py", line 625, in get_updates
    json_updates = apihelper.get_updates(self.token, offset, limit, timeout, allowed_updates, long_polling_timeout)
  File "/usr/local/lib/python3.10/dist-packages/telebot/apihelper.py", line 323, in get_updates
    return _make_request(token, method_url, params=payload)
  File "/usr/local/lib/python3.10/dist-packages/telebot/apihelper.py", line 164, in _make_request
    json_result = _check_result(method_name, result)
  File "/usr/local/lib/python3.10/dist-packages/telebot/apihelper.py", line 191, in _check_result
    raise ApiTelegramException(method_name, result, result_json)
telebot.apihelper.ApiTelegramException: A request to the Telegram API was unsuccessful. Error code: 429. Description: Too Many Requests: retry after 5
"
2024-01-03 01:10:15,943 (__init__.py:1088 MainThread) ERROR - TeleBot: "Threaded polling exception: A request to the Telegram API was unsuccessful. Error code: 429. Description: Too Many Requests: retry after 5"
2024-01-03 01:10:15,944 (__init__.py:1090 MainThread) ERROR - TeleBot: "Exception traceback:
Traceback (most recent call last):
  File "/usr/local/lib/python3.10/dist-packages/telebot/__init__.py", line 1081, in __threaded_polling
    polling_thread.raise_exceptions()
  File "/usr/local/lib/python3.10/dist-packages/telebot/util.py", line 108, in raise_exceptions
    raise self.exception_info
  File "/usr/local/lib/python3.10/dist-packages/telebot/util.py", line 90, in run
    task(*args, **kwargs)
  File "/usr/local/lib/python3.10/dist-packages/telebot/__init__.py", line 651, in __retrieve_updates
    updates = self.get_updates(offset=(self.last_update_id + 1),
  File "/usr/local/lib/python3.10/dist-packages/telebot/__init__.py", line 625, in get_updates
    json_updates = apihelper.get_updates(self.token, offset, limit, timeout, allowed_updates, long_polling_timeout)
  File "/usr/local/lib/python3.10/dist-packages/telebot/apihelper.py", line 323, in get_updates
    return _make_request(token, method_url, params=payload)
  File "/usr/local/lib/python3.10/dist-packages/telebot/apihelper.py", line 164, in _make_request
    json_result = _check_result(method_name, result)
  File "/usr/local/lib/python3.10/dist-packages/telebot/apihelper.py", line 191, in _check_result
    raise ApiTelegramException(method_name, result, result_json)
telebot.apihelper.ApiTelegramException: A request to the Telegram API was unsuccessful. Error code: 429. Description: Too Many Requests: retry after 5
"
2024-01-03 01:10:16,709 (__init__.py:1088 MainThread) ERROR - TeleBot: "Threaded polling exception: A request to the Telegram API was unsuccessful. Error code: 502. Description: Bad Gateway"
2024-01-03 01:10:16,709 (__init__.py:1090 MainThread) ERROR - TeleBot: "Exception traceback:
Traceback (most recent call last):
  File "/usr/local/lib/python3.10/dist-packages/telebot/__init__.py", line 1081, in __threaded_polling
    polling_thread.raise_exceptions()
  File "/usr/local/lib/python3.10/dist-packages/telebot/util.py", line 108, in raise_exceptions
    raise self.exception_info
  File "/usr/local/lib/python3.10/dist-packages/telebot/util.py", line 90, in run
    task(*args, **kwargs)
  File "/usr/local/lib/python3.10/dist-packages/telebot/__init__.py", line 651, in __retrieve_updates
    updates = self.get_updates(offset=(self.last_update_id + 1),
  File "/usr/local/lib/python3.10/dist-packages/telebot/__init__.py", line 625, in get_updates
    json_updates = apihelper.get_updates(self.token, offset, limit, timeout, allowed_updates, long_polling_timeout)
  File "/usr/local/lib/python3.10/dist-packages/telebot/apihelper.py", line 323, in get_updates
    return _make_request(token, method_url, params=payload)
  File "/usr/local/lib/python3.10/dist-packages/telebot/apihelper.py", line 164, in _make_request
    json_result = _check_result(method_name, result)
  File "/usr/local/lib/python3.10/dist-packages/telebot/apihelper.py", line 191, in _check_result
    raise ApiTelegramException(method_name, result, result_json)
telebot.apihelper.ApiTelegramException: A request to the Telegram API was unsuccessful. Error code: 502. Description: Bad Gateway
"
2024-01-03 01:10:17,765 (__init__.py:1088 MainThread) ERROR - TeleBot: "Threaded polling exception: A request to the Telegram API was unsuccessful. Error code: 502. Description: Bad Gateway"
2024-01-03 01:10:17,765 (__init__.py:1090 MainThread) ERROR - TeleBot: "Exception traceback:
Traceback (most recent call last):
  File "/usr/local/lib/python3.10/dist-packages/telebot/__init__.py", line 1081, in __threaded_polling
    polling_thread.raise_exceptions()
  File "/usr/local/lib/python3.10/dist-packages/telebot/util.py", line 108, in raise_exceptions
    raise self.exception_info
  File "/usr/local/lib/python3.10/dist-packages/telebot/util.py", line 90, in run
    task(*args, **kwargs)
  File "/usr/local/lib/python3.10/dist-packages/telebot/__init__.py", line 651, in __retrieve_updates
    updates = self.get_updates(offset=(self.last_update_id + 1),
  File "/usr/local/lib/python3.10/dist-packages/telebot/__init__.py", line 625, in get_updates
    json_updates = apihelper.get_updates(self.token, offset, limit, timeout, allowed_updates, long_polling_timeout)
  File "/usr/local/lib/python3.10/dist-packages/telebot/apihelper.py", line 323, in get_updates
    return _make_request(token, method_url, params=payload)
  File "/usr/local/lib/python3.10/dist-packages/telebot/apihelper.py", line 164, in _make_request
    json_result = _check_result(method_name, result)
  File "/usr/local/lib/python3.10/dist-packages/telebot/apihelper.py", line 191, in _check_result
    raise ApiTelegramException(method_name, result, result_json)
telebot.apihelper.ApiTelegramException: A request to the Telegram API was unsuccessful. Error code: 502. Description: Bad Gateway
"
Traceback (most recent call last):
  File "/usr/lib/python3/dist-packages/urllib3/connectionpool.py", line 445, in _make_request
    # Otherwise it looks like a bug in the code.
  File "<string>", line 3, in raise_from
  File "/usr/lib/python3/dist-packages/urllib3/connectionpool.py", line 440, in _make_request
    try:
  File "/usr/lib/python3.10/http/client.py", line 1375, in getresponse
    response.begin()
  File "/usr/lib/python3.10/http/client.py", line 318, in begin
    version, status, reason = self._read_status()
  File "/usr/lib/python3.10/http/client.py", line 279, in _read_status
    line = str(self.fp.readline(_MAXLINE + 1), "iso-8859-1")
  File "/usr/lib/python3.10/socket.py", line 705, in readinto
    return self._sock.recv_into(b)
  File "/usr/lib/python3.10/ssl.py", line 1274, in recv_into
    """
  File "/usr/lib/python3.10/ssl.py", line 1130, in read
    def session_reused(self):
TimeoutError: The read operation timed out

During handling of the above exception, another exception occurred:

Traceback (most recent call last):
  File "/usr/lib/python3/dist-packages/requests/adapters.py", line 439, in send
    resp = conn.urlopen(
  File "/usr/lib/python3/dist-packages/urllib3/connectionpool.py", line 755, in urlopen
    
  File "/usr/lib/python3/dist-packages/urllib3/util/retry.py", line 532, in increment
    raise six.reraise(type(error), error, _stacktrace)
  File "/usr/lib/python3/dist-packages/six.py", line 719, in reraise
    raise value
  File "/usr/lib/python3/dist-packages/urllib3/connectionpool.py", line 699, in urlopen
    # Make the request on the httplib connection object.
  File "/usr/lib/python3/dist-packages/urllib3/connectionpool.py", line 447, in _make_request
    except (SocketTimeout, BaseSSLError, SocketError) as e:
  File "/usr/lib/python3/dist-packages/urllib3/connectionpool.py", line 336, in _raise_timeout
    if isinstance(err, SocketTimeout):
urllib3.exceptions.ReadTimeoutError: HTTPSConnectionPool(host='api.telegram.org', port=443): Read timed out. (read timeout=25)

During handling of the above exception, another exception occurred:

Traceback (most recent call last):
  File "/TGbot/main.py", line 62, in <module>
    bot.polling(none_stop=True)
  File "/usr/local/lib/python3.10/dist-packages/telebot/__init__.py", line 1045, in polling
    self.__threaded_polling(non_stop=non_stop, interval=interval, timeout=timeout, long_polling_timeout=long_polling_timeout,
  File "/usr/local/lib/python3.10/dist-packages/telebot/__init__.py", line 1120, in __threaded_polling
    raise e
  File "/usr/local/lib/python3.10/dist-packages/telebot/__init__.py", line 1081, in __threaded_polling
    polling_thread.raise_exceptions()
  File "/usr/local/lib/python3.10/dist-packages/telebot/util.py", line 108, in raise_exceptions
    raise self.exception_info
  File "/usr/local/lib/python3.10/dist-packages/telebot/util.py", line 90, in run
    task(*args, **kwargs)
  File "/usr/local/lib/python3.10/dist-packages/telebot/__init__.py", line 651, in __retrieve_updates
    updates = self.get_updates(offset=(self.last_update_id + 1), 
  File "/usr/local/lib/python3.10/dist-packages/telebot/__init__.py", line 625, in get_updates
    json_updates = apihelper.get_updates(self.token, offset, limit, timeout, allowed_updates, long_polling_timeout)
  File "/usr/local/lib/python3.10/dist-packages/telebot/apihelper.py", line 323, in get_updates
    return _make_request(token, method_url, params=payload)
  File "/usr/local/lib/python3.10/dist-packages/telebot/apihelper.py", line 158, in _make_request
    result = _get_req_session().request(
  File "/usr/lib/python3/dist-packages/requests/sessions.py", line 544, in request
    resp = self.send(prep, **send_kwargs)
  File "/usr/lib/python3/dist-packages/requests/sessions.py", line 657, in send
    r = adapter.send(request, **kwargs)
  File "/usr/lib/python3/dist-packages/requests/adapters.py", line 529, in send
    raise ReadTimeout(e, request=request)
requests.exceptions.ReadTimeout: HTTPSConnectionPool(host='api.telegram.org', port=443): Read timed out. (read timeout=25)
